Workbook
Name Nhập_liệu_1: 'NHẬP LIỆU'!$A$6:$M$1048576
Name NHẬP_LIỆU: 'NHẬP LIỆU'!$B$6:$M$241

Sheet TỔNG HỢP
A1: BẢNG TỔNG HỢP XNT TỔNG NGÀNH HÀNG KHO TÂM SEN THÁNG 04 - 2024
A2: XNT | B2: TỒN ĐẦU KỲ | E2: NHẬP TRONG KỲ | H2: XUẤT TRONG KỲ | K2: TỒN CUỐI KỲ
A3: TÊN HÀNG HÓA | B3: TỒN ĐK CUỘN (KIỆN) | C3: TỒN ĐK THÙNG | D3: TỒN ĐK KHO (KG) | E3: NHẬP CUỘN (KIỆN) | F3: NHẬP THÙNG | G3: NHẬP KHO (KG) | H3: XUẤT CUỘN (KIỆN) | I3: XUẤT THÙNG | J3: XUẤT KG | K3: TỒN CK CUỘN (KIỆN) | L3: TỒN CK THÙNG | M3: TỒN CK KG
A4: COUCHE GLOSS HIKOTE | B4: 0 | C4: 0 | D4: 0 | E4: =SUMIF(#REF!,A4,#REF!) -> #N/A | F4: =SUMIF(#REF!,A4,#REF!) -> #N/A | G4: =SUMIF(#REF!,A4,#REF!) -> #N/A | H4: =SUMIF(#REF!,A4,#REF!) -> #N/A | I4: =SUMIF(#REF!,A4,#REF!) -> #N/A | J4: =SUMIF(#REF!,A4,#REF!) -> #N/A | K4: =SUMIF(#REF!,A4,#REF!) -> #N/A | L4: =SUMIF(#REF!,A4,#REF!) -> #N/A | M4: =SUMIF(#REF!,A4,#REF!) -> #N/A
A5: COUCHE NIPPON GLOSS | B5: 0 | C5: 0 | D5: 0 | E5: =SUMIF(#REF!,A5,#REF!) -> #N/A | F5: =SUMIF(#REF!,A5,#REF!) -> #N/A | G5: =SUMIF(#REF!,A5,#REF!) -> #N/A | H5: =SUMIF(#REF!,A5,#REF!) -> #N/A | I5: =SUMIF(#REF!,A5,#REF!) -> #N/A | J5: =SUMIF(#REF!,A5,#REF!) -> #N/A | K5: =SUMIF(#REF!,A5,#REF!) -> #N/A | L5: =SUMIF(#REF!,A5,#REF!) -> #N/A | M5: =SUMIF(#REF!,A5,#REF!) -> #N/A
A6: COUCHE NIPPON MATT | B6: 0 | C6: 0 | D6: 0 | E6: =SUMIF(#REF!,A6,#REF!) -> #N/A | F6: =SUMIF(#REF!,A6,#REF!) -> #N/A | G6: =SUMIF(#REF!,A6,#REF!) -> #N/A | H6: =SUMIF(#REF!,A6,#REF!) -> #N/A | I6: =SUMIF(#REF!,A6,#REF!) -> #N/A | J6: =SUMIF(#REF!,A6,#REF!) -> #N/A | K6: =SUMIF(#REF!,A6,#REF!) -> #N/A | L6: =SUMIF(#REF!,A6,#REF!) -> #N/A | M6: =SUMIF(#REF!,A6,#REF!) -> #N/A
A7: COUCHE HOKUETSU SIGMA MATT | B7: 0 | C7: 0 | D7: 0 | E7: =SUMIF(#REF!,A7,#REF!) -> #N/A | F7: =SUMIF(#REF!,A7,#REF!) -> #N/A | G7: =SUMIF(#REF!,A7,#REF!) -> #N/A | H7: =SUMIF(#REF!,A7,#REF!) -> #N/A | I7: =SUMIF(#REF!,A7,#REF!) -> #N/A | J7: =SUMIF(#REF!,A7,#REF!) -> #N/A | K7: =SUMIF(#REF!,A7,#REF!) -> #N/A | L7: =SUMIF(#REF!,A7,#REF!) -> #N/A | M7: =SUMIF(#REF!,A7,#REF!) -> #N/A
A8: COUCHE HOKUETSU ALPHA MATT | B8: 0 | C8: 0 | D8: 0 | E8: =SUMIF(#REF!,A8,#REF!) -> #N/A | F8: =SUMIF(#REF!,A8,#REF!) -> #N/A | G8: =SUMIF(#REF!,A8,#REF!) -> #N/A | H8: =SUMIF(#REF!,A8,#REF!) -> #N/A | I8: =SUMIF(#REF!,A8,#REF!) -> #N/A | J8: =SUMIF(#REF!,A8,#REF!) -> #N/A | K8: =SUMIF(#REF!,A8,#REF!) -> #N/A | L8: =SUMIF(#REF!,A8,#REF!) -> #N/A | M8: =SUMIF(#REF!,A8,#REF!) -> #N/A
A9: COUCHE HANSOL | B9: 0 | C9: 0 | D9: 0 | E9: =SUMIF(#REF!,A9,#REF!) -> #N/A | F9: =SUMIF(#REF!,A9,#REF!) -> #N/A | G9: =SUMIF(#REF!,A9,#REF!) -> #N/A | H9: =SUMIF(#REF!,A9,#REF!) -> #N/A | I9: =SUMIF(#REF!,A9,#REF!) -> #N/A | J9: =SUMIF(#REF!,A9,#REF!) -> #N/A | K9: =SUMIF(#REF!,A9,#REF!) -> #N/A | L9: =SUMIF(#REF!,A9,#REF!) -> #N/A | M9: =SUMIF(#REF!,A9,#REF!) -> #N/A
A10: DUPLEX KLEANARA | B10: 0 | C10: 0 | D10: 0 | E10: =SUMIF(#REF!,A10,#REF!) -> #N/A | F10: =SUMIF(#REF!,A10,#REF!) -> #N/A | G10: =SUMIF(#REF!,A10,#REF!) -> #N/A | H10: =SUMIF(#REF!,A10,#REF!) -> #N/A | I10: =SUMIF(#REF!,A10,#REF!) -> #N/A | J10: =SUMIF(#REF!,A10,#REF!) -> #N/A | K10: =SUMIF(#REF!,A10,#REF!) -> #N/A | L10: =SUMIF(#REF!,A10,#REF!) -> #N/A | M10: =SUMIF(#REF!,A10,#REF!) -> #N/A
A11: DUPLEX XSD GOLD MAPLE | B11: 0 | C11: 0 | D11: 0 | E11: =SUMIF(#REF!,A11,#REF!) -> #N/A | F11: =SUMIF(#REF!,A11,#REF!) -> #N/A | G11: =SUMIF(#REF!,A11,#REF!) -> #N/A | H11: =SUMIF(#REF!,A11,#REF!) -> #N/A | I11: =SUMIF(#REF!,A11,#REF!) -> #N/A | J11: =SUMIF(#REF!,A11,#REF!) -> #N/A | K11: =SUMIF(#REF!,A11,#REF!) -> #N/A | L11: =SUMIF(#REF!,A11,#REF!) -> #N/A | M11: =SUMIF(#REF!,A11,#REF!) -> #N/A
A12: DUPLEX XSD WHITE MAPLE | B12: 0 | C12: 0 | D12: 0 | E12: =SUMIF(#REF!,A12,#REF!) -> #N/A | F12: =SUMIF(#REF!,A12,#REF!) -> #N/A | G12: =SUMIF(#REF!,A12,#REF!) -> #N/A | H12: =SUMIF(#REF!,A12,#REF!) -> #N/A | I12: =SUMIF(#REF!,A12,#REF!) -> #N/A | J12: =SUMIF(#REF!,A12,#REF!) -> #N/A | K12: =SUMIF(#REF!,A12,#REF!) -> #N/A | L12: =SUMIF(#REF!,A12,#REF!) -> #N/A | M12: =SUMIF(#REF!,A12,#REF!) -> #N/A
A13: DUPLEX HANCHANG | B13: 0 | C13: 0 | D13: 0 | E13: =SUMIF(#REF!,A13,#REF!) -> #N/A | F13: =SUMIF(#REF!,A13,#REF!) -> #N/A | G13: =SUMIF(#REF!,A13,#REF!) -> #N/A | H13: =SUMIF(#REF!,A13,#REF!) -> #N/A | I13: =SUMIF(#REF!,A13,#REF!) -> #N/A | J13: =SUMIF(#REF!,A13,#REF!) -> #N/A | K13: =SUMIF(#REF!,A13,#REF!) -> #N/A | L13: =SUMIF(#REF!,A13,#REF!) -> #N/A | M13: =SUMIF(#REF!,A13,#REF!) -> #N/A
A14: IVORY NINGBO | B14: 0 | C14: 0 | D14: 0 | E14: =SUMIF(#REF!,A14,#REF!) -> #N/A | F14: =SUMIF(#REF!,A14,#REF!) -> #N/A | G14: =SUMIF(#REF!,A14,#REF!) -> #N/A | H14: =SUMIF(#REF!,A14,#REF!) -> #N/A | I14: =SUMIF(#REF!,A14,#REF!) -> #N/A | J14: =SUMIF(#REF!,A14,#REF!) -> #N/A | K14: =SUMIF(#REF!,A14,#REF!) -> #N/A | L14: =SUMIF(#REF!,A14,#REF!) -> #N/A | M14: =SUMIF(#REF!,A14,#REF!) -> #N/A
A15: IVORY IP SUN | B15: 0 | C15: 0 | D15: 0 | E15: =SUMIF(#REF!,A15,#REF!) -> #N/A | F15: =SUMIF(#REF!,A15,#REF!) -> #N/A | G15: =SUMIF(#REF!,A15,#REF!) -> #N/A | H15: =SUMIF(#REF!,A15,#REF!) -> #N/A | I15: =SUMIF(#REF!,A15,#REF!) -> #N/A | J15: =SUMIF(#REF!,A15,#REF!) -> #N/A | K15: =SUMIF(#REF!,A15,#REF!) -> #N/A | L15: =SUMIF(#REF!,A15,#REF!) -> #N/A | M15: =SUMIF(#REF!,A15,#REF!) -> #N/A
... A26: COREBROAD | B26: 0 | C26: 0 | D26: 0 | E26: =SUMIF(#REF!,A26,#REF!) -> #N/A | F26: =SUMIF(#REF!,A26,#REF!) -> #N/A | G26: =SUMIF(#REF!,A26,#REF!) -> #N/A | H26: =SUMIF(#REF!,A26,#REF!) -> #N/A | I26: =SUMIF(#REF!,A26,#REF!) -> #N/A | J26: =SUMIF(#REF!,A26,#REF!) -> #N/A | K26: =SUMIF(#REF!,A26,#REF!) -> #N/A | L26: =SUMIF(#REF!,A26,#REF!) -> #N/A | M26: =SUMIF(#REF!,A26,#REF!) -> #N/A
A27: TỔNG | B27: =SUM(B4:B26) -> 0 | C27: =SUM(C4:C26) -> 0 | D27: =SUM(D4:D26) -> 0 | E27: =SUM(E4:E26) -> #N/A | F27: =SUM(F4:F26) -> #N/A | G27: =SUM(G4:G26) -> #N/A | H27: =SUM(H4:H26) -> #N/A | I27: =SUM(I4:I26) -> #N/A | ... M27: =SUM(M4:M26) -> #N/A
B28: =SUMIFS(#REF!,#REF!,#REF!,#REF!,#REF!) -> #N/A | C28: =SUMIFS(#REF!,#REF!,#REF!,#REF!,#REF!) -> #N/A | D28: =SUMIFS(#REF!,#REF!,#REF!,#REF!,#REF!) -> #N/A | H28: =SUMIFS(#REF!,#REF!,#REF!,#REF!,#REF!) -> #N/A | I28: =SUMIFS(#REF!,#REF!,#REF!,#REF!,#REF!) -> #N/A | J28: =SUMIFS(#REF!,#REF!,#REF!,#REF!,#REF!) -> #N/A | K28: =+K27-#REF! -> #N/A | L28: =+L27-#REF! -> #N/A | M28: =+M27-#REF! -> #N/A

Sheet NHẬP LIỆU
A4: STT | B4: Chứng từ | D4: Diễn giải | E4: Hàng Hóa | H4: Quy cách SP | K4: Số Lượng | M4: Tên nhà cung cấp/ Khách hàng | N4: Bộ Phận
B5: Số ĐH | C5: Ngày xuất / nhập | E5: Mã hàng | F5: Tên hàng | G5: ĐVT | K5: Nhập | L5: Xuất
A6: =+ROW()-5 -> 1 | C6: 45475 | D6: Nhập Kho NVL | E6: INIB21065 | F6: =+IFERROR(VLOOKUP(E6,'DANH MỤC'!$C:$H,2,0),"") -> Ivory Ningbo | G6: =+IFERROR(VLOOKUP(E6,'DANH MỤC'!$C:$H,6,0),"") -> Kg | H6: =+IFERROR(VLOOKUP(E6,'DANH MỤC'!$C:$H,3,0),"") -> 210 | I6: =+IFERROR(VLOOKUP(E6,'DANH MỤC'!$C:$H,4,0),"") -> 65 | J6: =+IFERROR(VLOOKUP(E6,'DANH MỤC'!$C:$H,5,0),"") | K6: 315 | M6: Cuộn dở AVP chuyển ra
A7: =+ROW()-5 -> 2 | C7: 45475 | D7: Nhập Kho NVL | E7: INIB210109 | F7: =+IFERROR(VLOOKUP(E7,'DANH MỤC'!$C:$H,2,0),"") -> Ivory Ningbo | G7: =+IFERROR(VLOOKUP(E7,'DANH MỤC'!$C:$H,6,0),"") -> Kg | H7: =+IFERROR(VLOOKUP(E7,'DANH MỤC'!$C:$H,3,0),"") -> 210 | I7: =+IFERROR(VLOOKUP(E7,'DANH MỤC'!$C:$H,4,0),"") -> 109 | J7: =+IFERROR(VLOOKUP(E7,'DANH MỤC'!$C:$H,5,0),"") | K7: 1030 | M7: AVP chuyển ra
A8: =+ROW()-5 -> 3 | C8: 45475 | D8: Nhập Kho NVL | E8: INIB21086 | F8: =+IFERROR(VLOOKUP(E8,'DANH MỤC'!$C:$H,2,0),"") -> Ivory Ningbo | G8: =+IFERROR(VLOOKUP(E8,'DANH MỤC'!$C:$H,6,0),"") -> Kg | H8: =+IFERROR(VLOOKUP(E8,'DANH MỤC'!$C:$H,3,0),"") -> 210 | I8: =+IFERROR(VLOOKUP(E8,'DANH MỤC'!$C:$H,4,0),"") -> 86 | J8: =+IFERROR(VLOOKUP(E8,'DANH MỤC'!$C:$H,5,0),"") | K8: 71 | M8: Cuộn dở AVP chuyển ra, lõi to
A9: =+ROW()-5 -> 4 | C9: 45475 | D9: Nhập Kho NVL | E9: INIB23079 | F9: =+IFERROR(VLOOKUP(E9,'DANH MỤC'!$C:$H,2,0),"") -> Ivory Ningbo | G9: =+IFERROR(VLOOKUP(E9,'DANH MỤC'!$C:$H,6,0),"") -> Kg | H9: =+IFERROR(VLOOKUP(E9,'DANH MỤC'!$C:$H,3,0),"") -> 230 | I9: =+IFERROR(VLOOKUP(E9,'DANH MỤC'!$C:$H,4,0),"") -> 79 | J9: =+IFERROR(VLOOKUP(E9,'DANH MỤC'!$C:$H,5,0),"") | K9: 609 | M9: AVP chuyển ra
A10: =+ROW()-5 -> 5 | C10: 45475 | D10: Nhập Kho NVL | E10: INIB23079 | F10: =+IFERROR(VLOOKUP(E10,'DANH MỤC'!$C:$H,2,0),"") -> Ivory Ningbo | G10: =+IFERROR(VLOOKUP(E10,'DANH MỤC'!$C:$H,6,0),"") -> Kg | H10: =+IFERROR(VLOOKUP(E10,'DANH MỤC'!$C:$H,3,0),"") -> 230 | I10: =+IFERROR(VLOOKUP(E10,'DANH MỤC'!$C:$H,4,0),"") -> 79 | J10: =+IFERROR(VLOOKUP(E10,'DANH MỤC'!$C:$H,5,0),"") | K10: 75 | M10: Cuộn dở AVP chuyển ra
A11: =+ROW()-5 -> 6 | C11: 45475 | D11: Nhập Kho NVL | E11: IIPS210109 | F11: =+IFERROR(VLOOKUP(E11,'DANH MỤC'!$C:$H,2,0),"") -> Ivory IPSUN | G11: =+IFERROR(VLOOKUP(E11,'DANH MỤC'!$C:$H,6,0),"") -> Kg | H11: =+IFERROR(VLOOKUP(E11,'DANH MỤC'!$C:$H,3,0),"") -> 210 | I11: =+IFERROR(VLOOKUP(E11,'DANH MỤC'!$C:$H,4,0),"") -> 109 | J11: =+IFERROR(VLOOKUP(E11,'DANH MỤC'!$C:$H,5,0),"") | K11: 4212 | M11: AVP chuyển ra
A12: =+ROW()-5 -> 7 | C12: 45475 | D12: Nhập Kho NVL | E12: IIPS230109 | F12: =+IFERROR(VLOOKUP(E12,'DANH MỤC'!$C:$H,2,0),"") -> Ivory IPSUN | G12: =+IFERROR(VLOOKUP(E12,'DANH MỤC'!$C:$H,6,0),"") -> Kg | H12: =+IFERROR(VLOOKUP(E12,'DANH MỤC'!$C:$H,3,0),"") -> 230 | I12: =+IFERROR(VLOOKUP(E12,'DANH MỤC'!$C:$H,4,0),"") -> 109 | J12: =+IFERROR(VLOOKUP(E12,'DANH MỤC'!$C:$H,5,0),"") | K12: 912 | M12: Cuộn dở AVP chuyển ra
A13: =+ROW()-5 -> 8 | C13: 45475 | D13: Nhập Kho NVL | E13: IIPS25084 | F13: =+IFERROR(VLOOKUP(E13,'DANH MỤC'!$C:$H,2,0),"") -> Ivory IPSUN | G13: =+IFERROR(VLOOKUP(E13,'DANH MỤC'!$C:$H,6,0),"") -> Kg | H13: =+IFERROR(VLOOKUP(E13,'DANH MỤC'!$C:$H,3,0),"") -> 250 | I13: =+IFERROR(VLOOKUP(E13,'DANH MỤC'!$C:$H,4,0),"") -> 84 | J13: =+IFERROR(VLOOKUP(E13,'DANH MỤC'!$C:$H,5,0),"") | K13: 128 | M13: Cuộn dở AVP chuyển ra
A14: =+ROW()-5 -> 9 | C14: 45475 | D14: Nhập Kho NVL | E14: INIB250109 | F14: =+IFERROR(VLOOKUP(E14,'DANH MỤC'!$C:$H,2,0),"") -> Ivory Ningbo | G14: =+IFERROR(VLOOKUP(E14,'DANH MỤC'!$C:$H,6,0),"") -> Kg | H14: =+IFERROR(VLOOKUP(E14,'DANH MỤC'!$C:$H,3,0),"") -> 250 | I14: =+IFERROR(VLOOKUP(E14,'DANH MỤC'!$C:$H,4,0),"") -> 109 | J14: =+IFERROR(VLOOKUP(E14,'DANH MỤC'!$C:$H,5,0),"") | K14: 140 | M14: Cuộn dở AVP chuyển ra
A15: =+ROW()-5 -> 10 | C15: 45475 | D15: Nhập Kho NVL | E15: IIPS250109 | F15: =+IFERROR(VLOOKUP(E15,'DANH MỤC'!$C:$H,2,0),"") -> Ivory IPSUN | G15: =+IFERROR(VLOOKUP(E15,'DANH MỤC'!$C:$H,6,0),"") -> Kg | H15: =+IFERROR(VLOOKUP(E15,'DANH MỤC'!$C:$H,3,0),"") -> 250 | I15: =+IFERROR(VLOOKUP(E15,'DANH MỤC'!$C:$H,4,0),"") -> 109 | J15: =+IFERROR(VLOOKUP(E15,'DANH MỤC'!$C:$H,5,0),"") | K15: 74 | M15: Cuộn dở AVP chuyển ra
A16: =+ROW()-5 -> 11 | C16: 45475 | D16: Nhập Kho NVL | E16: INIB25065 | F16: =+IFERROR(VLOOKUP(E16,'DANH MỤC'!$C:$H,2,0),"") -> Ivory Ningbo | G16: =+IFERROR(VLOOKUP(E16,'DANH MỤC'!$C:$H,6,0),"") -> Kg | H16: =+IFERROR(VLOOKUP(E16,'DANH MỤC'!$C:$H,3,0),"") -> 250 | I16: =+IFERROR(VLOOKUP(E16,'DANH MỤC'!$C:$H,4,0),"") -> 65 | J16: =+IFERROR(VLOOKUP(E16,'DANH MỤC'!$C:$H,5,0),"") | K16: 110 | M16: Cuộn dở AVP chuyển ra
A17: =+ROW()-5 -> 12 | C17: 45485 | D17: Nhập Mua Vật Tư | E17: GIAYBAOLG | F17: =+IFERROR(VLOOKUP(E17,'DANH MỤC'!$C:$H,2,0),"") -> Giấy bao gói lưỡi gà | G17: =+IFERROR(VLOOKUP(E17,'DANH MỤC'!$C:$H,6,0),"") -> Kg | H17: =+IFERROR(VLOOKUP(E17,'DANH MỤC'!$C:$H,3,0),"") | I17: =+IFERROR(VLOOKUP(E17,'DANH MỤC'!$C:$H,4,0),"") | J17: =+IFERROR(VLOOKUP(E17,'DANH MỤC'!$C:$H,5,0),"") | K17: 180
A18: =+ROW()-5 -> 13 | C18: 45485 | D18: Nhập Mua Vật Tư | E18: OG.12.7.1000 | F18: =+IFERROR(VLOOKUP(E18,'DANH MỤC'!$C:$H,2,0),"") -> Ống lõi giấy phi 120x7x1000mm | G18: =+IFERROR(VLOOKUP(E18,'DANH MỤC'!$C:$H,6,0),"") -> Cái | H18: =+IFERROR(VLOOKUP(E18,'DANH MỤC'!$C:$H,3,0),"") -> 120 | I18: =+IFERROR(VLOOKUP(E18,'DANH MỤC'!$C:$H,4,0),"") -> 70 | J18: =+IFERROR(VLOOKUP(E18,'DANH MỤC'!$C:$H,5,0),"") -> 1000 | K18: 72
A19: =+ROW()-5 -> 14 | C19: 45498 | D19: Nhập Kho NVL | E19: IIPS210109 | F19: =+IFERROR(VLOOKUP(E19,'DANH MỤC'!$C:$H,2,0),"") -> Ivory IPSUN | G19: =+IFERROR(VLOOKUP(E19,'DANH MỤC'!$C:$H,6,0),"") -> Kg | H19: =+IFERROR(VLOOKUP(E19,'DANH MỤC'!$C:$H,3,0),"") -> 210 | I19: =+IFERROR(VLOOKUP(E19,'DANH MỤC'!$C:$H,4,0),"") -> 109 | J19: =+IFERROR(VLOOKUP(E19,'DANH MỤC'!$C:$H,5,0),"") | K19: 5983 | M19: AVP chuyển ra 5CN+2 CD
A20: =+ROW()-5 -> 15 | C20: 45498 | D20: Nhập Kho NVL | E20: IIPS230109 | F20: =+IFERROR(VLOOKUP(E20,'DANH MỤC'!$C:$H,2,0),"") -> Ivory IPSUN | G20: =+IFERROR(VLOOKUP(E20,'DANH MỤC'!$C:$H,6,0),"") -> Kg | H20: =+IFERROR(VLOOKUP(E20,'DANH MỤC'!$C:$H,3,0),"") -> 230 | I20: =+IFERROR(VLOOKUP(E20,'DANH MỤC'!$C:$H,4,0),"") -> 109 | J20: =+IFERROR(VLOOKUP(E20,'DANH MỤC'!$C:$H,5,0),"") | K20: 11308 | M20: AVP chuyển ra 11CN
A21: =+ROW()-5 -> 16 | C21: 45498 | D21: Nhập Kho NVL | E21: IIPS250109 | F21: =+IFERROR(VLOOKUP(E21,'DANH MỤC'!$C:$H,2,0),"") -> Ivory IPSUN | G21: =+IFERROR(VLOOKUP(E21,'DANH MỤC'!$C:$H,6,0),"") -> Kg | H21: =+IFERROR(VLOOKUP(E21,'DANH MỤC'!$C:$H,3,0),"") -> 250 | I21: =+IFERROR(VLOOKUP(E21,'DANH MỤC'!$C:$H,4,0),"") -> 109 | J21: =+IFERROR(VLOOKUP(E21,'DANH MỤC'!$C:$H,5,0),"") | K21: 60 | M21: Cuộn dở AVP chuyển ra
A22: =+ROW()-5 -> 17 | C22: 45498 | D22: Nhập Kho NVL | E22: IIPS25084 | F22: =+IFERROR(VLOOKUP(E22,'DANH MỤC'!$C:$H,2,0),"") -> Ivory IPSUN | G22: =+IFERROR(VLOOKUP(E22,'DANH MỤC'!$C:$H,6,0),"") -> Kg | H22: =+IFERROR(VLOOKUP(E22,'DANH MỤC'!$C:$H,3,0),"") -> 250 | I22: =+IFERROR(VLOOKUP(E22,'DANH MỤC'!$C:$H,4,0),"") -> 84 | J22: =+IFERROR(VLOOKUP(E22,'DANH MỤC'!$C:$H,5,0),"") | K22: 21 | M22: Cuộn dở AVP chuyển ra
A23: =+ROW()-5 -> 18 | C23: 45498 | D23: Nhập Mua Vật Tư | E23: OG.12.7.1000 | F23: =+IFERROR(VLOOKUP(E23,'DANH MỤC'!$C:$H,2,0),"") -> Ống lõi giấy phi 120x7x1000mm | G23: =+IFERROR(VLOOKUP(E23,'DANH MỤC'!$C:$H,6,0),"") -> Cái | H23: =+IFERROR(VLOOKUP(E23,'DANH MỤC'!$C:$H,3,0),"") -> 120 | I23: =+IFERROR(VLOOKUP(E23,'DANH MỤC'!$C:$H,4,0),"") -> 70 | J23: =+IFERROR(VLOOKUP(E23,'DANH MỤC'!$C:$H,5,0),"") -> 1000 | K23: 264
A24: =+ROW()-5 -> 19 | C24: 45498 | D24: Nhập Mua Vật Tư | E24: PL12.12.130 | F24: =+IFERROR(VLOOKUP(E24,'DANH MỤC'!$C:$H,2,0),"") -> Pallet gỗ 1200x1200x130mm | G24: =+IFERROR(VLOOKUP(E24,'DANH MỤC'!$C:$H,6,0),"") -> Bộ | H24: =+IFERROR(VLOOKUP(E24,'DANH MỤC'!$C:$H,3,0),"") -> 1200 | I24: =+IFERROR(VLOOKUP(E24,'DANH MỤC'!$C:$H,4,0),"") -> 1200 | J24: =+IFERROR(VLOOKUP(E24,'DANH MỤC'!$C:$H,5,0),"") -> 130 | K24: 16
A25: =+ROW()-5 -> 20 | C25: 45498 | D25: Nhập Mua Vật Tư | E25: KRAFT | F25: =+IFERROR(VLOOKUP(E25,'DANH MỤC'!$C:$H,2,0),"") -> Kraft nâu LG (cuộn) | G25: =+IFERROR(VLOOKUP(E25,'DANH MỤC'!$C:$H,6,0),"") -> Kg | H25: =+IFERROR(VLOOKUP(E25,'DANH MỤC'!$C:$H,3,0),"") | I25: =+IFERROR(VLOOKUP(E25,'DANH MỤC'!$C:$H,4,0),"") | J25: =+IFERROR(VLOOKUP(E25,'DANH MỤC'!$C:$H,5,0),"") | K25: 1562
A26: =+ROW()-5 -> 21 | C26: 45498 | D26: Nhập Mua Vật Tư | E26: DAY.DAI.PET | F26: =+IFERROR(VLOOKUP(E26,'DANH MỤC'!$C:$H,2,0),"") -> Dây đai PET xanh (B) | G26: =+IFERROR(VLOOKUP(E26,'DANH MỤC'!$C:$H,6,0),"") -> Kg | H26: =+IFERROR(VLOOKUP(E26,'DANH MỤC'!$C:$H,3,0),"") | I26: =+IFERROR(VLOOKUP(E26,'DANH MỤC'!$C:$H,4,0),"") | J26: =+IFERROR(VLOOKUP(E26,'DANH MỤC'!$C:$H,5,0),"") | K26: 300
A27: =+ROW()-5 -> 22 | C27: 45498 | D27: Nhập Mua Vật Tư | E27: MANGPE | F27: =+IFERROR(VLOOKUP(E27,'DANH MỤC'!$C:$H,2,0),"") -> Màng Strecth Film 5.0-0.6kg | G27: =+IFERROR(VLOOKUP(E27,'DANH MỤC'!$C:$H,6,0),"") -> Kg | H27: =+IFERROR(VLOOKUP(E27,'DANH MỤC'!$C:$H,3,0),"") | I27: =+IFERROR(VLOOKUP(E27,'DANH MỤC'!$C:$H,4,0),"") | J27: =+IFERROR(VLOOKUP(E27,'DANH MỤC'!$C:$H,5,0),"") | K27: =35.2+55 -> 90.2
A28: =+ROW()-5 -> 23 | C28: 45499 | D28: Nhập Kho NVL | E28: INIB250109 | F28: =+IFERROR(VLOOKUP(E28,'DANH MỤC'!$C:$H,2,0),"") -> Ivory Ningbo | G28: =+IFERROR(VLOOKUP(E28,'DANH MỤC'!$C:$H,6,0),"") -> Kg | H28: =+IFERROR(VLOOKUP(E28,'DANH MỤC'!$C:$H,3,0),"") -> 250 | I28: =+IFERROR(VLOOKUP(E28,'DANH MỤC'!$C:$H,4,0),"") -> 109 | J28: =+IFERROR(VLOOKUP(E28,'DANH MỤC'!$C:$H,5,0),"") | K28: 2943 | M28: Nhập hàng của Chí Nguyên
A29: =+ROW()-5 -> 24 | C29: 45499 | D29: Nhập Kho NVL | E29: INIB25065 | F29: =+IFERROR(VLOOKUP(E29,'DANH MỤC'!$C:$H,2,0),"") -> Ivory Ningbo | G29: =+IFERROR(VLOOKUP(E29,'DANH MỤC'!$C:$H,6,0),"") -> Kg | H29: =+IFERROR(VLOOKUP(E29,'DANH MỤC'!$C:$H,3,0),"") -> 250 | I29: =+IFERROR(VLOOKUP(E29,'DANH MỤC'!$C:$H,4,0),"") -> 65 | J29: =+IFERROR(VLOOKUP(E29,'DANH MỤC'!$C:$H,5,0),"") | K29: 3510 | M29: Nhập hàng của Chí Nguyên
A30: =+ROW()-5 -> 25 | C30: 45499 | D30: Nhập Kho NVL | E30: INIB25075 | F30: =+IFERROR(VLOOKUP(E30,'DANH MỤC'!$C:$H,2,0),"") -> Ivory Ningbo | G30: =+IFERROR(VLOOKUP(E30,'DANH MỤC'!$C:$H,6,0),"") -> Kg | H30: =+IFERROR(VLOOKUP(E30,'DANH MỤC'!$C:$H,3,0),"") -> 250 | I30: =+IFERROR(VLOOKUP(E30,'DANH MỤC'!$C:$H,4,0),"") -> 75 | J30: =+IFERROR(VLOOKUP(E30,'DANH MỤC'!$C:$H,5,0),"") | K30: 3375 | M30: Nhập hàng của Chí Nguyên
A31: =+ROW()-5 -> 26 | C31: 45499 | D31: Nhập Mua Vật Tư | E31: MANGPE | F31: =+IFERROR(VLOOKUP(E31,'DANH MỤC'!$C:$H,2,0),"") -> Màng Strecth Film 5.0-0.6kg | G31: =+IFERROR(VLOOKUP(E31,'DANH MỤC'!$C:$H,6,0),"") -> Kg | H31: =+IFERROR(VLOOKUP(E31,'DANH MỤC'!$C:$H,3,0),"") | I31: =+IFERROR(VLOOKUP(E31,'DANH MỤC'!$C:$H,4,0),"") | J31: =+IFERROR(VLOOKUP(E31,'DANH MỤC'!$C:$H,5,0),"") | K31: 220
A32: =+ROW()-5 -> 27 | C32: 45499 | D32: Nhập Mua Vật Tư | E32: DAY.DAI.PET | F32: =+IFERROR(VLOOKUP(E32,'DANH MỤC'!$C:$H,2,0),"") -> Dây đai PET xanh (B) | G32: =+IFERROR(VLOOKUP(E32,'DANH MỤC'!$C:$H,6,0),"") -> Kg | H32: =+IFERROR(VLOOKUP(E32,'DANH MỤC'!$C:$H,3,0),"") | I32: =+IFERROR(VLOOKUP(E32,'DANH MỤC'!$C:$H,4,0),"") | J32: =+IFERROR(VLOOKUP(E32,'DANH MỤC'!$C:$H,5,0),"") | K32: 200
A33: =+ROW()-5 -> 28 | C33: 45499 | D33: Xuất vật tư sx | E33: GIAYBAOLG | F33: =+IFERROR(VLOOKUP(E33,'DANH MỤC'!$C:$H,2,0),"") -> Giấy bao gói lưỡi gà | G33: =+IFERROR(VLOOKUP(E33,'DANH MỤC'!$C:$H,6,0),"") -> Kg | H33: =+IFERROR(VLOOKUP(E33,'DANH MỤC'!$C:$H,3,0),"") | I33: =+IFERROR(VLOOKUP(E33,'DANH MỤC'!$C:$H,4,0),"") | J33: =+IFERROR(VLOOKUP(E33,'DANH MỤC'!$C:$H,5,0),"") | L33: 12.45
A34: =+ROW()-5 -> 29 | C34: 45499 | D34: Xuất vật tư sx | E34: OG.12.7.1000 | F34: =+IFERROR(VLOOKUP(E34,'DANH MỤC'!$C:$H,2,0),"") -> Ống lõi giấy phi 120x7x1000mm | G34: =+IFERROR(VLOOKUP(E34,'DANH MỤC'!$C:$H,6,0),"") -> Cái | H34: =+IFERROR(VLOOKUP(E34,'DANH MỤC'!$C:$H,3,0),"") -> 120 | I34: =+IFERROR(VLOOKUP(E34,'DANH MỤC'!$C:$H,4,0),"") -> 70 | J34: =+IFERROR(VLOOKUP(E34,'DANH MỤC'!$C:$H,5,0),"") -> 1000 | L34: 70
A35: =+ROW()-5 -> 30 | C35: 45499 | D35: Xuất vật tư sx | E35: PL12.12.130 | F35: =+IFERROR(VLOOKUP(E35,'DANH MỤC'!$C:$H,2,0),"") -> Pallet gỗ 1200x1200x130mm | G35: =+IFERROR(VLOOKUP(E35,'DANH MỤC'!$C:$H,6,0),"") -> Bộ | H35: =+IFERROR(VLOOKUP(E35,'DANH MỤC'!$C:$H,3,0),"") -> 1200 | I35: =+IFERROR(VLOOKUP(E35,'DANH MỤC'!$C:$H,4,0),"") -> 1200 | J35: =+IFERROR(VLOOKUP(E35,'DANH MỤC'!$C:$H,5,0),"") -> 130 | L35: 11
A36: =+ROW()-5 -> 31 | C36: 45499 | D36: Xuất vật tư sx | E36: MANGPE | F36: =+IFERROR(VLOOKUP(E36,'DANH MỤC'!$C:$H,2,0),"") -> Màng Strecth Film 5.0-0.6kg | G36: =+IFERROR(VLOOKUP(E36,'DANH MỤC'!$C:$H,6,0),"") -> Kg | H36: =+IFERROR(VLOOKUP(E36,'DANH MỤC'!$C:$H,3,0),"") | I36: =+IFERROR(VLOOKUP(E36,'DANH MỤC'!$C:$H,4,0),"") | J36: =+IFERROR(VLOOKUP(E36,'DANH MỤC'!$C:$H,5,0),"") | L36: 6.73
A37: =+ROW()-5 -> 32 | C37: 45499 | D37: Xuất vật tư sx | E37: DAY.DAI.PET | F37: =+IFERROR(VLOOKUP(E37,'DANH MỤC'!$C:$H,2,0),"") -> Dây đai PET xanh (B) | G37: =+IFERROR(VLOOKUP(E37,'DANH MỤC'!$C:$H,6,0),"") -> Kg | H37: =+IFERROR(VLOOKUP(E37,'DANH MỤC'!$C:$H,3,0),"") | I37: =+IFERROR(VLOOKUP(E37,'DANH MỤC'!$C:$H,4,0),"") | J37: =+IFERROR(VLOOKUP(E37,'DANH MỤC'!$C:$H,5,0),"") | L37: 11.39
A38: =+ROW()-5 -> 33 | C38: 45502 | D38: Nhập Mua Vật Tư | E38: PL11.11.130 | F38: =+IFERROR(VLOOKUP(E38,'DANH MỤC'!$C:$H,2,0),"") -> Pallet gỗ 1100x1100x130mm | G38: =+IFERROR(VLOOKUP(E38,'DANH MỤC'!$C:$H,6,0),"") -> Bộ | H38: =+IFERROR(VLOOKUP(E38,'DANH MỤC'!$C:$H,3,0),"") -> 1100 | I38: =+IFERROR(VLOOKUP(E38,'DANH MỤC'!$C:$H,4,0),"") -> 1100 | J38: =+IFERROR(VLOOKUP(E38,'DANH MỤC'!$C:$H,5,0),"") -> 130 | K38: 50
A39: =+ROW()-5 -> 34 | B39: 01.07/LGT-BBMN | C39: 45506 | D39: Nhập Thành Phẩm LSX 39.2024 | E39: LGT250/90-TS | F39: =+IFERROR(VLOOKUP(E39,'DANH MỤC'!$C:$H,2,0),"") -> Lưỡi gà trắng 90mm x 800m x 250gsm | G39: =+IFERROR(VLOOKUP(E39,'DANH MỤC'!$C:$H,6,0),"") -> Cuộn | H39: =+IFERROR(VLOOKUP(E39,'DANH MỤC'!$C:$H,3,0),"") -> 250 | I39: =+IFERROR(VLOOKUP(E39,'DANH MỤC'!$C:$H,4,0),"") -> 90 | J39: =+IFERROR(VLOOKUP(E39,'DANH MỤC'!$C:$H,5,0),"") -> 800 | K39: 528
A40: =+ROW()-5 -> 35 | C40: 45506 | D40: Xuất LG BBMN | E40: LGT250/90-TS | F40: =+IFERROR(VLOOKUP(E40,'DANH MỤC'!$C:$H,2,0),"") -> Lưỡi gà trắng 90mm x 800m x 250gsm | G40: =+IFERROR(VLOOKUP(E40,'DANH MỤC'!$C:$H,6,0),"") -> Cuộn | H40: =+IFERROR(VLOOKUP(E40,'DANH MỤC'!$C:$H,3,0),"") -> 250 | I40: =+IFERROR(VLOOKUP(E40,'DANH MỤC'!$C:$H,4,0),"") -> 90 | J40: =+IFERROR(VLOOKUP(E40,'DANH MỤC'!$C:$H,5,0),"") -> 800 | L40: 520 | M40: BBMN
A41: =+ROW()-5 -> 36 | B41: 24/LGT/08 | C41: 45511 | D41: Xuất NVL Lsx 40.2024 | E41: IIPS230109 | F41: =+IFERROR(VLOOKUP(E41,'DANH MỤC'!$C:$H,2,0),"") -> Ivory IPSUN | G41: =+IFERROR(VLOOKUP(E41,'DANH MỤC'!$C:$H,6,0),"") -> Kg | H41: =+IFERROR(VLOOKUP(E41,'DANH MỤC'!$C:$H,3,0),"") -> 230 | I41: =+IFERROR(VLOOKUP(E41,'DANH MỤC'!$C:$H,4,0),"") -> 109 | J41: =+IFERROR(VLOOKUP(E41,'DANH MỤC'!$C:$H,5,0),"") | L41: =7080-427 -> 6653
A42: =+ROW()-5 -> 37 | C42: 45511 | D42: Xuất vật tư sx | E42: PL12.12.130 | F42: =+IFERROR(VLOOKUP(E42,'DANH MỤC'!$C:$H,2,0),"") -> Pallet gỗ 1200x1200x130mm | G42: =+IFERROR(VLOOKUP(E42,'DANH MỤC'!$C:$H,6,0),"") -> Bộ | H42: =+IFERROR(VLOOKUP(E42,'DANH MỤC'!$C:$H,3,0),"") -> 1200 | I42: =+IFERROR(VLOOKUP(E42,'DANH MỤC'!$C:$H,4,0),"") -> 1200 | J42: =+IFERROR(VLOOKUP(E42,'DANH MỤC'!$C:$H,5,0),"") -> 130 | L42: 5
A43: =+ROW()-5 -> 38 | C43: 45511 | D43: Xuất vật tư sx | E43: PL11.11.130 | F43: =+IFERROR(VLOOKUP(E43,'DANH MỤC'!$C:$H,2,0),"") -> Pallet gỗ 1100x1100x130mm | G43: =+IFERROR(VLOOKUP(E43,'DANH MỤC'!$C:$H,6,0),"") -> Bộ | H43: =+IFERROR(VLOOKUP(E43,'DANH MỤC'!$C:$H,3,0),"") -> 1100 | I43: =+IFERROR(VLOOKUP(E43,'DANH MỤC'!$C:$H,4,0),"") -> 1100 | J43: =+IFERROR(VLOOKUP(E43,'DANH MỤC'!$C:$H,5,0),"") -> 130 | L43: 1
...

Sheet THÀNH PHẨM
A7: TỒN KHO THÀNH PHẨM
A8: STT | B8: MÃ TP | C8: TÊN HÀNG | D8: ĐL (GSM) | E8: KHỔ (MM) | F8: DÀI (M) | G8: ĐVT | H8: TỒN ĐK | I8: NHẬP | J8: XUẤT | K8: TỒN CK | L8: GHI CHÚ | M8: TÌNH TRẠNG HÀNG HÓA
A9: =+ROW()-8 -> 1 | B9: LGT210/71-TS | C9: Lưỡi gà trắng 71mm x 800m x 210gsm | D9: 210 | E9: 71 | F9: 800 | G9: Cuộn | H9: 988 | I9: =+SUMIF('NHẬP LIỆU'!$E:$E,'THÀNH PHẨM'!$B9,'NHẬP LIỆU'!$K:$K) -> 25004 | J9: =+SUMIF('NHẬP LIỆU'!$E:$E,'THÀNH PHẨM'!$B9,'NHẬP LIỆU'!$L:$L) -> 25992 | K9: =+'THÀNH PHẨM'!$H9+'THÀNH PHẨM'!$I9-'THÀNH PHẨM'!$J9 -> 0 | O9: =+('THÀNH PHẨM'!$D9*'THÀNH PHẨM'!$E9*'THÀNH PHẨM'!$F9/1000000)*'THÀNH PHẨM'!$K9 -> 0
A10: =+ROW()-8 -> 2 | B10: LGT210/83-TS | C10: Lưỡi gà trắng 83mm x 800m x 210gsm | D10: 210 | E10: 83 | F10: 800 | G10: Cuộn | H10: 30 | I10: =+SUMIF('NHẬP LIỆU'!$E:$E,'THÀNH PHẨM'!$B10,'NHẬP LIỆU'!$K:$K) -> 632 | J10: =+SUMIF('NHẬP LIỆU'!$E:$E,'THÀNH PHẨM'!$B10,'NHẬP LIỆU'!$L:$L) -> 661 | K10: =+'THÀNH PHẨM'!$H10+'THÀNH PHẨM'!$I10-'THÀNH PHẨM'!$J10 -> 1 | L10: 1 | O10: =+('THÀNH PHẨM'!$D10*'THÀNH PHẨM'!$E10*'THÀNH PHẨM'!$F10/1000000)*'THÀNH PHẨM'!$K10 -> 13.944
A11: 3 | B11: LGT210/88-TS | C11: Lưỡi gà trắng 88mm x 800m x 210gsm | D11: 210 | E11: 88 | F11: 800 | G11: Cuộn | H11: 0 | I11: =+SUMIF('NHẬP LIỆU'!$E:$E,'THÀNH PHẨM'!$B11,'NHẬP LIỆU'!$K:$K) -> 260 | J11: =+SUMIF('NHẬP LIỆU'!$E:$E,'THÀNH PHẨM'!$B11,'NHẬP LIỆU'!$L:$L) -> 260 | K11: =+'THÀNH PHẨM'!$H11+'THÀNH PHẨM'!$I11-'THÀNH PHẨM'!$J11 -> 0 | O11: =+('THÀNH PHẨM'!$D11*'THÀNH PHẨM'!$E11*'THÀNH PHẨM'!$F11/1000000)*'THÀNH PHẨM'!$K11 -> 0
A12: =+ROW()-8 -> 4 | B12: LGT210/91-TS | C12: Lưỡi gà trắng 91mm x 800m x 210gsm | D12: 210 | E12: 91 | F12: 800 | G12: Cuộn | H12: 0 | I12: =+SUMIF('NHẬP LIỆU'!$E:$E,'THÀNH PHẨM'!$B12,'NHẬP LIỆU'!$K:$K) -> 80 | J12: =+SUMIF('NHẬP LIỆU'!$E:$E,'THÀNH PHẨM'!$B12,'NHẬP LIỆU'!$L:$L) -> 80 | K12: =+'THÀNH PHẨM'!$H12+'THÀNH PHẨM'!$I12-'THÀNH PHẨM'!$J12 -> 0 | O12: =+('THÀNH PHẨM'!$D12*'THÀNH PHẨM'!$E12*'THÀNH PHẨM'!$F12/1000000)*'THÀNH PHẨM'!$K12 -> 0
A13: =+ROW()-8 -> 5 | B13: LGT210/96.5-TS | C13: Lưỡi gà trắng 96.5mm x 800m x 210gsm | D13: 210 | E13: 96.5 | F13: 800 | G13: Cuộn | H13: 0 | I13: =+SUMIF('NHẬP LIỆU'!$E:$E,'THÀNH PHẨM'!$B13,'NHẬP LIỆU'!$K:$K) -> 22 | J13: =+SUMIF('NHẬP LIỆU'!$E:$E,'THÀNH PHẨM'!$B13,'NHẬP LIỆU'!$L:$L) -> 22 | K13: =+'THÀNH PHẨM'!$H13+'THÀNH PHẨM'!$I13-'THÀNH PHẨM'!$J13 -> 0
A14: =+ROW()-8 -> 6 | B14: LGT210/95-TS | C14: Lưỡi gà trắng 95mm x 800m x 210gsm | D14: 210 | E14: 95 | F14: 800 | G14: Cuộn | H14: 426 | I14: =+SUMIF('NHẬP LIỆU'!$E:$E,'THÀNH PHẨM'!$B14,'NHẬP LIỆU'!$K:$K) -> 9592 | J14: =+SUMIF('NHẬP LIỆU'!$E:$E,'THÀNH PHẨM'!$B14,'NHẬP LIỆU'!$L:$L) -> 8945 | K14: =+'THÀNH PHẨM'!$H14+'THÀNH PHẨM'!$I14-'THÀNH PHẨM'!$J14 -> 1073 | L14: (2*60+18*52 + LẺ 17) | O14: =+('THÀNH PHẨM'!$D14*'THÀNH PHẨM'!$E14*'THÀNH PHẨM'!$F14/1000000)*'THÀNH PHẨM'!$K14 -> 17125.08
A15: =+ROW()-8 -> 7 | B15: LGT230/75-TS | C15: Lưỡi gà trắng 75mm x 800m x 230gsm | D15: 230 | E15: 75 | F15: 800 | G15: Cuộn | H15: 0 | I15: =+SUMIF('NHẬP LIỆU'!$E:$E,'THÀNH PHẨM'!$B15,'NHẬP LIỆU'!$K:$K) -> 186 | J15: =+SUMIF('NHẬP LIỆU'!$E:$E,'THÀNH PHẨM'!$B15,'NHẬP LIỆU'!$L:$L) -> 1 | K15: =+'THÀNH PHẨM'!$H15+'THÀNH PHẨM'!$I15-'THÀNH PHẨM'!$J15 -> 185 | L15: (3*60)+5
A16: =+ROW()-8 -> 8 | B16: LGT230/95-TS | C16: Lưỡi gà trắng 95mm x 800m x 230gsm | D16: 230 | E16: 95 | F16: 800 | G16: Cuộn | H16: 5 | I16: =+SUMIF('NHẬP LIỆU'!$E:$E,'THÀNH PHẨM'!$B16,'NHẬP LIỆU'!$K:$K) -> 5654 | J16: =+SUMIF('NHẬP LIỆU'!$E:$E,'THÀNH PHẨM'!$B16,'NHẬP LIỆU'!$L:$L) -> 5346 | K16: =+'THÀNH PHẨM'!$H16+'THÀNH PHẨM'!$I16-'THÀNH PHẨM'!$J16 -> 313 | L16: (5*60)+5+8 | O16: =+('THÀNH PHẨM'!$D16*'THÀNH PHẨM'!$E16*'THÀNH PHẨM'!$F16/1000000)*'THÀNH PHẨM'!$K16 -> 5471.24
A17: =+ROW()-8 -> 9 | B17: LGT230/97-TS | C17: Lưỡi gà trắng 97mm x 800m x 230gsm | D17: 230 | E17: 97 | F17: 800 | G17: Cuộn | H17: 0 | I17: =+SUMIF('NHẬP LIỆU'!$E:$E,'THÀNH PHẨM'!$B17,'NHẬP LIỆU'!$K:$K) -> 1 | J17: =+SUMIF('NHẬP LIỆU'!$E:$E,'THÀNH PHẨM'!$B17,'NHẬP LIỆU'!$L:$L) -> 1 | K17: =+'THÀNH PHẨM'!$H17+'THÀNH PHẨM'!$I17-'THÀNH PHẨM'!$J17 -> 0 | O17: =+('THÀNH PHẨM'!$D17*'THÀNH PHẨM'!$E17*'THÀNH PHẨM'!$F17/1000000)*'THÀNH PHẨM'!$K17 -> 0
A18: =+ROW()-8 -> 10 | B18: LGT230/98-TS | C18: Lưỡi gà trắng 98mm x 800m x 230gsm | D18: 230 | E18: 98 | F18: 800 | G18: Cuộn | H18: 145 | I18: =+SUMIF('NHẬP LIỆU'!$E:$E,'THÀNH PHẨM'!$B18,'NHẬP LIỆU'!$K:$K) -> 3849 | J18: =+SUMIF('NHẬP LIỆU'!$E:$E,'THÀNH PHẨM'!$B18,'NHẬP LIỆU'!$L:$L) -> 3994 | K18: =+'THÀNH PHẨM'!$H18+'THÀNH PHẨM'!$I18-'THÀNH PHẨM'!$J18 -> 0 | O18: =+('THÀNH PHẨM'!$D18*'THÀNH PHẨM'!$E18*'THÀNH PHẨM'!$F18/1000000)*'THÀNH PHẨM'!$K18 -> 0
A19: =+ROW()-8 -> 11 | B19: LGT250/90-TS | C19: Lưỡi gà trắng 90mm x 800m x 250gsm | D19: 250 | E19: 90 | F19: 800 | G19: Cuộn | H19: 0 | I19: =+SUMIF('NHẬP LIỆU'!$E:$E,'THÀNH PHẨM'!$B19,'NHẬP LIỆU'!$K:$K) -> 15143 | J19: =+SUMIF('NHẬP LIỆU'!$E:$E,'THÀNH PHẨM'!$B19,'NHẬP LIỆU'!$L:$L) -> 13739 | K19: =+'THÀNH PHẨM'!$H19+'THÀNH PHẨM'!$I19-'THÀNH PHẨM'!$J19 -> 1404 | L19: (27*52) | O19: =+('THÀNH PHẨM'!$D19*'THÀNH PHẨM'!$E19*'THÀNH PHẨM'!$F19/1000000)*'THÀNH PHẨM'!$K19 -> 25272
C20: TỔNG | H20: =SUM(H9:H19) -> 1594 | I20: =SUM(I9:I19) -> 60423 | J20: =SUM(J9:J19) -> 59041 | K20: =SUM(K9:K19) -> 2976 | O20: =SUM(O9:O19) -> 47882.264

Sheet BÁN TP
A1: TỒN KHO BTP
A2: STT | B2: MÃ BTP | C2: TÊN HÀNG | D2: ĐL (GSM) | E2: KHỔ (MM) | F2: DÀI (M) | G2: ĐVT | H2: TỒN CUỘN | I2: KG | J2: GHI CHÚ
A3: =+ROW()-2 -> 1
A4: =+ROW()-2 -> 2
A5: =+ROW()-2 -> 3
A6: =+ROW()-2 -> 4
A7: =+ROW()-2 -> 5
A8: =+ROW()-2 -> 6
A9: =+ROW()-2 -> 7
A10: =+ROW()-2 -> 8

Sheet NVL
A8: TỔNG HỢP XUẤT NHẬP TỒN NVL
K9: =+SUBTOTAL(9,$K$11:$K$608) -> 127778
A10: STT | B10: MÃ HÀNG | C10: TÊN HÀNG | D10: ĐL | E10: KHỔ | F10: DÀI | G10: ĐVT | H10: TỒN ĐẦU | I10: NHẬP | J10: XUẤT | K10: TỒN CUỒI | L10: GHI CHÚ
A11: =+SUBTOTAL(3,$B$11:B11) -> 1 | B11: INIB21065 | C11: Ivory Ningbo | D11: 210 | E11: 65 | G11: Kg | H11: 0 | I11: =+SUMIF('NHẬP LIỆU'!$E:$E,NVL!$B11,'NHẬP LIỆU'!$K:$K) -> 315 | J11: =+SUMIF('NHẬP LIỆU'!$E:$E,NVL!$B11,'NHẬP LIỆU'!$L:$L) -> 315 | K11: =+NVL!$H11+NVL!$I11-NVL!$J11 -> 0
A12: =+SUBTOTAL(3,$B$11:B12) -> 2 | B12: INIB21070 | C12: Ivory Ningbo | D12: 210 | E12: 70 | G12: Kg | H12: 0 | I12: =+SUMIF('NHẬP LIỆU'!$E:$E,NVL!$B12,'NHẬP LIỆU'!$K:$K) -> 3834 | J12: =+SUMIF('NHẬP LIỆU'!$E:$E,NVL!$B12,'NHẬP LIỆU'!$L:$L) -> 3834 | K12: =+NVL!$H12+NVL!$I12-NVL!$J12 -> 0
A13: =+SUBTOTAL(3,$B$11:B13) -> 3 | B13: INIB21079 | C13: Ivory Ningbo | D13: 210 | E13: 79 | G13: Kg | H13: 0 | I13: =+SUMIF('NHẬP LIỆU'!$E:$E,NVL!$B13,'NHẬP LIỆU'!$K:$K) -> 20166 | J13: =+SUMIF('NHẬP LIỆU'!$E:$E,NVL!$B13,'NHẬP LIỆU'!$L:$L) -> 20166 | K13: =+NVL!$H13+NVL!$I13-NVL!$J13 -> 0
A14: =+SUBTOTAL(3,$B$11:B14) -> 4 | B14: INIB21086 | C14: Ivory Ningbo | D14: 210 | E14: 86 | G14: Kg | H14: 0 | I14: =+SUMIF('NHẬP LIỆU'!$E:$E,NVL!$B14,'NHẬP LIỆU'!$K:$K) -> 11453 | J14: =+SUMIF('NHẬP LIỆU'!$E:$E,NVL!$B14,'NHẬP LIỆU'!$L:$L) -> 11453 | K14: =+NVL!$H14+NVL!$I14-NVL!$J14 -> 0
A15: =+SUBTOTAL(3,$B$11:B15) -> 5 | B15: INIB210106 | C15: Ivory Ningbo | D15: 210 | E15: 106 | G15: Kg | I15: =+SUMIF('NHẬP LIỆU'!$E:$E,NVL!$B15,'NHẬP LIỆU'!$K:$K) -> 20328 | J15: =+SUMIF('NHẬP LIỆU'!$E:$E,NVL!$B15,'NHẬP LIỆU'!$L:$L) -> 10648 | K15: =+NVL!$H15+NVL!$I15-NVL!$J15 -> 9680 | L15: 10 C * 968 kg
A16: =+SUBTOTAL(3,$B$11:B16) -> 6 | B16: INIB210108 | C16: Ivory Ningbo | D16: 210 | E16: 108 | G16: Kg | H16: 0 | I16: =+SUMIF('NHẬP LIỆU'!$E:$E,NVL!$B16,'NHẬP LIỆU'!$K:$K) -> 277347 | J16: =+SUMIF('NHẬP LIỆU'!$E:$E,NVL!$B16,'NHẬP LIỆU'!$L:$L) -> 220388 | K16: =+NVL!$H16+NVL!$I16-NVL!$J16 -> 56959 | L16: 57C*987 + DC 700KG
A17: =+SUBTOTAL(3,$B$11:B17) -> 7 | B17: INIB210109 | C17: Ivory Ningbo | D17: 210 | E17: 109 | G17: Kg | H17: 0 | I17: =+SUMIF('NHẬP LIỆU'!$E:$E,NVL!$B17,'NHẬP LIỆU'!$K:$K) -> 206218 | J17: =+SUMIF('NHẬP LIỆU'!$E:$E,NVL!$B17,'NHẬP LIỆU'!$L:$L) -> 206218 | K17: =+NVL!$H17+NVL!$I17-NVL!$J17 -> 0
A18: =+SUBTOTAL(3,$B$11:B18) -> 8 | B18: INIB23065 | C18: Ivory Ningbo | D18: 230 | E18: 65 | G18: Kg | H18: 0 | I18: =+SUMIF('NHẬP LIỆU'!$E:$E,NVL!$B18,'NHẬP LIỆU'!$K:$K) -> 30 | J18: =+SUMIF('NHẬP LIỆU'!$E:$E,NVL!$B18,'NHẬP LIỆU'!$L:$L) -> 30 | K18: =+NVL!$H18+NVL!$I18-NVL!$J18 -> 0
A19: =+SUBTOTAL(3,$B$11:B19) -> 9 | B19: INIB23079 | C19: Ivory Ningbo | D19: 230 | E19: 79 | G19: Kg | H19: 0 | I19: =+SUMIF('NHẬP LIỆU'!$E:$E,NVL!$B19,'NHẬP LIỆU'!$K:$K) -> 684 | J19: =+SUMIF('NHẬP LIỆU'!$E:$E,NVL!$B19,'NHẬP LIỆU'!$L:$L) -> 75 | K19: =+NVL!$H19+NVL!$I19-NVL!$J19 -> 609 | L19: 1CD 609kg AVP - nòng to
A20: =+SUBTOTAL(3,$B$11:B20) -> 10 | B20: INIB230106 | C20: Ivory Ningbo | D20: 230 | E20: 106 | G20: Kg | H20: 0 | I20: =+SUMIF('NHẬP LIỆU'!$E:$E,NVL!$B20,'NHẬP LIỆU'!$K:$K) -> 35187 | J20: =+SUMIF('NHẬP LIỆU'!$E:$E,NVL!$B20,'NHẬP LIỆU'!$L:$L) -> 17369 | K20: =+NVL!$H20+NVL!$I20-NVL!$J20 -> 17818 | L20: 18C *951kg + CD700kg
A21: =+SUBTOTAL(3,$B$11:B21) -> 11 | B21: INIB230108 | C21: Ivory Ningbo | D21: 230 | E21: 108 | G21: Kg | H21: 0 | I21: =+SUMIF('NHẬP LIỆU'!$E:$E,NVL!$B21,'NHẬP LIỆU'!$K:$K) -> 86241 | J21: =+SUMIF('NHẬP LIỆU'!$E:$E,NVL!$B21,'NHẬP LIỆU'!$L:$L) -> 58859 | K21: =+NVL!$H21+NVL!$I21-NVL!$J21 -> 27382 | L21: 28C*969 + 1CD 250kg
A22: =+SUBTOTAL(3,$B$11:B22) -> 12 | B22: INIB230109 | C22: Ivory Ningbo | D22: 230 | E22: 109 | G22: Kg | H22: 0 | I22: =+SUMIF('NHẬP LIỆU'!$E:$E,NVL!$B22,'NHẬP LIỆU'!$K:$K) -> 92705 | J22: =+SUMIF('NHẬP LIỆU'!$E:$E,NVL!$B22,'NHẬP LIỆU'!$L:$L) -> 87985 | K22: =+NVL!$H22+NVL!$I22-NVL!$J22 -> 4720 | L22: 4C * 990 + 1CD 760kG
A23: =+SUBTOTAL(3,$B$11:B23) -> 13 | B23: INIB25065 | C23: Ivory Ningbo | D23: 250 | E23: 65 | G23: Kg | H23: 0 | I23: =+SUMIF('NHẬP LIỆU'!$E:$E,NVL!$B23,'NHẬP LIỆU'!$K:$K) -> 3620 | J23: =+SUMIF('NHẬP LIỆU'!$E:$E,NVL!$B23,'NHẬP LIỆU'!$L:$L) -> 3620 | K23: =+NVL!$H23+NVL!$I23-NVL!$J23 -> 0
A24: =+SUBTOTAL(3,$B$11:B24) -> 14 | B24: INIB25075 | C24: Ivory Ningbo | D24: 250 | E24: 75 | G24: Kg | H24: 0 | I24: =+SUMIF('NHẬP LIỆU'!$E:$E,NVL!$B24,'NHẬP LIỆU'!$K:$K) -> 3375 | J24: =+SUMIF('NHẬP LIỆU'!$E:$E,NVL!$B24,'NHẬP LIỆU'!$L:$L) -> 3375 | K24: =+NVL!$H24+NVL!$I24-NVL!$J24 -> 0
A25: =+SUBTOTAL(3,$B$11:B25) -> 15 | B25: INIB250100 | C25: Ivory Ningbo | D25: 250 | E25: 100 | G25: Kg | H25: 0 | I25: =+SUMIF('NHẬP LIỆU'!$E:$E,NVL!$B25,'NHẬP LIỆU'!$K:$K) -> 17100 | J25: =+SUMIF('NHẬP LIỆU'!$E:$E,NVL!$B25,'NHẬP LIỆU'!$L:$L) -> 17100 | K25: =+NVL!$H25+NVL!$I25-NVL!$J25 -> 0
A26: =+SUBTOTAL(3,$B$11:B26) -> 16 | B26: INIB250102 | C26: Ivory Ningbo | D26: 250 | E26: 102 | G26: Kg | H26: 0 | I26: =+SUMIF('NHẬP LIỆU'!$E:$E,NVL!$B26,'NHẬP LIỆU'!$K:$K) -> 5508 | J26: =+SUMIF('NHẬP LIỆU'!$E:$E,NVL!$B26,'NHẬP LIỆU'!$L:$L) -> 5508 | K26: =+NVL!$H26+NVL!$I26-NVL!$J26 -> 0
A27: =+SUBTOTAL(3,$B$11:B27) -> 17 | B27: INIB250109 | C27: Ivory Ningbo | D27: 250 | E27: 109 | G27: Kg | H27: 0 | I27: =+SUMIF('NHẬP LIỆU'!$E:$E,NVL!$B27,'NHẬP LIỆU'!$K:$K) -> 259559 | J27: =+SUMIF('NHẬP LIỆU'!$E:$E,NVL!$B27,'NHẬP LIỆU'!$L:$L) -> 248949 | K27: =+NVL!$H27+NVL!$I27-NVL!$J27 -> 10610 | L27: 10C *981kg + CD 800KG
A28: =+SUBTOTAL(3,$B$11:B28) -> 18 | B28: IIPS210109 | C28: Ivory IPSUN | D28: 210 | E28: 109 | G28: Kg | H28: 0 | I28: =+SUMIF('NHẬP LIỆU'!$E:$E,NVL!$B28,'NHẬP LIỆU'!$K:$K) -> 10195 | J28: =+SUMIF('NHẬP LIỆU'!$E:$E,NVL!$B28,'NHẬP LIỆU'!$L:$L) -> 10195 | K28: =+NVL!$H28+NVL!$I28-NVL!$J28 -> 0
A29: =+SUBTOTAL(3,$B$11:B29) -> 19 | B29: IIPS230109 | C29: Ivory IPSUN | D29: 230 | E29: 109 | G29: Kg | H29: 0 | I29: =+SUMIF('NHẬP LIỆU'!$E:$E,NVL!$B29,'NHẬP LIỆU'!$K:$K) -> 12220 | J29: =+SUMIF('NHẬP LIỆU'!$E:$E,NVL!$B29,'NHẬP LIỆU'!$L:$L) -> 12220 | K29: =+NVL!$H29+NVL!$I29-NVL!$J29 -> 0
A30: =+SUBTOTAL(3,$B$11:B30) -> 20 | B30: IIPS25084 | C30: Ivory IPSUN | D30: 250 | E30: 84 | G30: Kg | H30: 0 | I30: =+SUMIF('NHẬP LIỆU'!$E:$E,NVL!$B30,'NHẬP LIỆU'!$K:$K) -> 149 | J30: =+SUMIF('NHẬP LIỆU'!$E:$E,NVL!$B30,'NHẬP LIỆU'!$L:$L) -> 149 | K30: =+NVL!$H30+NVL!$I30-NVL!$J30 -> 0
A31: =+SUBTOTAL(3,$B$11:B31) -> 21 | B31: IIPS250109 | C31: Ivory IPSUN | D31: 250 | E31: 109 | G31: Kg | H31: 0 | I31: =+SUMIF('NHẬP LIỆU'!$E:$E,NVL!$B31,'NHẬP LIỆU'!$K:$K) -> 134 | J31: =+SUMIF('NHẬP LIỆU'!$E:$E,NVL!$B31,'NHẬP LIỆU'!$L:$L) -> 134 | K31: =+NVL!$H31+NVL!$I31-NVL!$J31 -> 0
A32: =+SUBTOTAL(3,$B$11:B32) -> 21 | H32: 0 | I32: =+SUMIF('NHẬP LIỆU'!$E:$E,NVL!$B32,'NHẬP LIỆU'!$K:$K) -> 0 | J32: =+SUMIF('NHẬP LIỆU'!$E:$E,NVL!$B32,'NHẬP LIỆU'!$L:$L) -> 0 | K32: =+NVL!$H32+NVL!$I32-NVL!$J32 -> 0
A33: =+SUBTOTAL(3,$B$11:B33) -> 21 | I33: =+SUMIF('NHẬP LIỆU'!$E:$E,NVL!$B33,'NHẬP LIỆU'!$K:$K) -> 0 | J33: =+SUMIF('NHẬP LIỆU'!$E:$E,NVL!$B33,'NHẬP LIỆU'!$L:$L) -> 0 | K33: =+NVL!$H33+NVL!$I33-NVL!$J33 -> 0
A34: =+SUBTOTAL(3,$B$11:B34) -> 21 | I34: =+SUMIF('NHẬP LIỆU'!$E:$E,NVL!$B34,'NHẬP LIỆU'!$K:$K) -> 0 | J34: =+SUMIF('NHẬP LIỆU'!$E:$E,NVL!$B34,'NHẬP LIỆU'!$L:$L) -> 0 | K34: =+NVL!$H34+NVL!$I34-NVL!$J34 -> 0
A35: =+SUBTOTAL(3,$B$11:B35) -> 21 | I35: =+SUMIF('NHẬP LIỆU'!$E:$E,NVL!$B35,'NHẬP LIỆU'!$K:$K) -> 0 | J35: =+SUMIF('NHẬP LIỆU'!$E:$E,NVL!$B35,'NHẬP LIỆU'!$L:$L) -> 0 | K35: =+NVL!$H35+NVL!$I35-NVL!$J35 -> 0
A36: =+SUBTOTAL(3,$B$11:B36) -> 21 | I36: =+SUMIF('NHẬP LIỆU'!$E:$E,NVL!$B36,'NHẬP LIỆU'!$K:$K) -> 0 | J36: =+SUMIF('NHẬP LIỆU'!$E:$E,NVL!$B36,'NHẬP LIỆU'!$L:$L) -> 0 | K36: =+NVL!$H36+NVL!$I36-NVL!$J36 -> 0
A37: =+SUBTOTAL(3,$B$11:B37) -> 21 | I37: =+SUMIF('NHẬP LIỆU'!$E:$E,NVL!$B37,'NHẬP LIỆU'!$K:$K) -> 0 | J37: =+SUMIF('NHẬP LIỆU'!$E:$E,NVL!$B37,'NHẬP LIỆU'!$L:$L) -> 0 | K37: =+NVL!$H37+NVL!$I37-NVL!$J37 -> 0
A38: =+SUBTOTAL(3,$B$11:B38) -> 21 | I38: =+SUMIF('NHẬP LIỆU'!$E:$E,NVL!$B38,'NHẬP LIỆU'!$K:$K) -> 0 | J38: =+SUMIF('NHẬP LIỆU'!$E:$E,NVL!$B38,'NHẬP LIỆU'!$L:$L) -> 0 | K38: =+NVL!$H38+NVL!$I38-NVL!$J38 -> 0
A39: =+SUBTOTAL(3,$B$11:B39) -> 21 | I39: =+SUMIF('NHẬP LIỆU'!$E:$E,NVL!$B39,'NHẬP LIỆU'!$K:$K) -> 0 | J39: =+SUMIF('NHẬP LIỆU'!$E:$E,NVL!$B39,'NHẬP LIỆU'!$L:$L) -> 0 | K39: =+NVL!$H39+NVL!$I39-NVL!$J39 -> 0
A40: =+SUBTOTAL(3,$B$11:B40) -> 21 | I40: =+SUMIF('NHẬP LIỆU'!$E:$E,NVL!$B40,'NHẬP LIỆU'!$K:$K) -> 0 | J40: =+SUMIF('NHẬP LIỆU'!$E:$E,NVL!$B40,'NHẬP LIỆU'!$L:$L) -> 0 | K40: =+NVL!$H40+NVL!$I40-NVL!$J40 -> 0
A41: =+SUBTOTAL(3,$B$11:B41) -> 21 | I41: =+SUMIF('NHẬP LIỆU'!$E:$E,NVL!$B41,'NHẬP LIỆU'!$K:$K) -> 0 | J41: =+SUMIF('NHẬP LIỆU'!$E:$E,NVL!$B41,'NHẬP LIỆU'!$L:$L) -> 0 | K41: =+NVL!$H41+NVL!$I41-NVL!$J41 -> 0
A42: =+SUBTOTAL(3,$B$11:B42) -> 21 | I42: =+SUMIF('NHẬP LIỆU'!$E:$E,NVL!$B42,'NHẬP LIỆU'!$K:$K) -> 0 | J42: =+SUMIF('NHẬP LIỆU'!$E:$E,NVL!$B42,'NHẬP LIỆU'!$L:$L) -> 0 | K42: =+NVL!$H42+NVL!$I42-NVL!$J42 -> 0
A43: =+SUBTOTAL(3,$B$11:B43) -> 21 | I43: =+SUMIF('NHẬP LIỆU'!$E:$E,NVL!$B43,'NHẬP LIỆU'!$K:$K) -> 0 | J43: =+SUMIF('NHẬP LIỆU'!$E:$E,NVL!$B43,'NHẬP LIỆU'!$L:$L) -> 0 | K43: =+NVL!$H43+NVL!$I43-NVL!$J43 -> 0
A44: =+SUBTOTAL(3,$B$11:B44) -> 21 | I44: =+SUMIF('NHẬP LIỆU'!$E:$E,NVL!$B44,'NHẬP LIỆU'!$K:$K) -> 0 | J44: =+SUMIF('NHẬP LIỆU'!$E:$E,NVL!$B44,'NHẬP LIỆU'!$L:$L) -> 0 | K44: =+NVL!$H44+NVL!$I44-NVL!$J44 -> 0
... A612: =+SUBTOTAL(3,$B$11:B612) -> 21 | I612: =+SUMIF('NHẬP LIỆU'!$E:$E,NVL!$B612,'NHẬP LIỆU'!$K:$K) -> 0 | J612: =+SUMIF('NHẬP LIỆU'!$E:$E,NVL!$B612,'NHẬP LIỆU'!$L:$L) -> 0 | K612: =+NVL!$H612+NVL!$I612-NVL!$J612 -> 0

Sheet VẬT TƯ
C1: VẬT TƯ SẢN XUẤT
H2: =+SUBTOTAL(9,$H$4:$H$63) -> 14366.139
A3: STT | B3: MÃ HÀNG | C3: TÊN HÀNG | D3: ĐVT | E3: TỒN ĐẦU | F3: NHẬP | G3: XUẤT | H3: TỒN | I3: GHI CHÚ
A4: =+ROW()-3 -> 1 | B4: PL12.12.130 | C4: Pallet gỗ 1200x1200x130mm | D4: Bộ | E4: 3 | F4: =+SUMIF('NHẬP LIỆU'!$E:$E,'VẬT TƯ'!B4,'NHẬP LIỆU'!$K:$K) -> 446 | G4: =+SUMIF('NHẬP LIỆU'!$E:$E,'VẬT TƯ'!B4,'NHẬP LIỆU'!$L:$L) -> 447 | H4: =+E4+F4-G4 -> 2
A5: =+ROW()-3 -> 2 | B5: PL11.11.130 | C5: Pallet gỗ 1100x1100x130mm | D5: Bộ | E5: 0 | F5: =+SUMIF('NHẬP LIỆU'!$E:$E,'VẬT TƯ'!B5,'NHẬP LIỆU'!$K:$K) -> 712 | G5: =+SUMIF('NHẬP LIỆU'!$E:$E,'VẬT TƯ'!B5,'NHẬP LIỆU'!$L:$L) -> 662 | H5: =+E5+F5-G5 -> 50
A6: =+ROW()-3 -> 3 | B6: NEP1.15 | C6: Nẹp gỗ pallet dài 1.15m | D6: Cái | E6: 0 | F6: =+SUMIF('NHẬP LIỆU'!$E:$E,'VẬT TƯ'!B6,'NHẬP LIỆU'!$K:$K) -> 1200 | G6: =+SUMIF('NHẬP LIỆU'!$E:$E,'VẬT TƯ'!B6,'NHẬP LIỆU'!$L:$L) -> 1200 | H6: =+E6+F6-G6 -> 0
A7: =+ROW()-3 -> 4 | B7: OG.12.7.71 | C7: Ống lõi giấy phi 120x7x71mm | D7: Cái | E7: 0 | F7: =+SUMIF('NHẬP LIỆU'!$E:$E,'VẬT TƯ'!B7,'NHẬP LIỆU'!$K:$K) -> 34000 | G7: =+SUMIF('NHẬP LIỆU'!$E:$E,'VẬT TƯ'!B7,'NHẬP LIỆU'!$L:$L) -> 24702 | H7: =+E7+F7-G7 -> 9298
A8: =+ROW()-3 -> 5 | B8: OG.12.7.88 | C8: Ống lõi giấy phi 120x7x88mm | D8: Cái | E8: 0 | F8: =+SUMIF('NHẬP LIỆU'!$E:$E,'VẬT TƯ'!B8,'NHẬP LIỆU'!$K:$K) -> 260 | G8: =+SUMIF('NHẬP LIỆU'!$E:$E,'VẬT TƯ'!B8,'NHẬP LIỆU'!$L:$L) -> 260 | H8: =+E8+F8-G8 -> 0
A9: =+ROW()-3 -> 6 | B9: OG.12.7.90 | C9: Ống lõi giấy phi 120x7x90mm | D9: Cái | E9: 0 | F9: =+SUMIF('NHẬP LIỆU'!$E:$E,'VẬT TƯ'!B9,'NHẬP LIỆU'!$K:$K) -> 14000 | G9: =+SUMIF('NHẬP LIỆU'!$E:$E,'VẬT TƯ'!B9,'NHẬP LIỆU'!$L:$L) -> 13850 | H9: =+E9+F9-G9 -> 150
A10: =+ROW()-3 -> 7 | B10: OG.12.7.95 | C10: Ống lõi giấy phi 120x7x95mm | D10: Cái | E10: 0 | F10: =+SUMIF('NHẬP LIỆU'!$E:$E,'VẬT TƯ'!B10,'NHẬP LIỆU'!$K:$K) -> 16500 | G10: =+SUMIF('NHẬP LIỆU'!$E:$E,'VẬT TƯ'!B10,'NHẬP LIỆU'!$L:$L) -> 14729 | H10: =+E10+F10-G10 -> 1771 | K10: =1.1*1.1*0.23 -> 0.2783
A11: =+ROW()-3 -> 8 | B11: OG.12.7.98 | C11: Ống lõi giấy phi 120x7x98mm | D11: Cái | E11: 0 | F11: =+SUMIF('NHẬP LIỆU'!$E:$E,'VẬT TƯ'!B11,'NHẬP LIỆU'!$K:$K) -> 5000 | G11: =+SUMIF('NHẬP LIỆU'!$E:$E,'VẬT TƯ'!B11,'NHẬP LIỆU'!$L:$L) -> 3605 | H11: =+E11+F11-G11 -> 1395
A12: =+ROW()-3 -> 9 | B12: OG.12.7.1000 | C12: Ống lõi giấy phi 120x7x1000mm | D12: Cái | E12: 0 | F12: =+SUMIF('NHẬP LIỆU'!$E:$E,'VẬT TƯ'!B12,'NHẬP LIỆU'!$K:$K) -> 436 | G12: =+SUMIF('NHẬP LIỆU'!$E:$E,'VẬT TƯ'!B12,'NHẬP LIỆU'!$L:$L) -> 370 | H12: =+E12+F12-G12 -> 66
A13: =+ROW()-3 -> 10 | B13: MANGPE | C13: Màng Strecth Film 5.0-0.6kg | D13: Kg | E13: 36.62 | F13: =+SUMIF('NHẬP LIỆU'!$E:$E,'VẬT TƯ'!B13,'NHẬP LIỆU'!$K:$K) -> 640.2 | G13: =+SUMIF('NHẬP LIỆU'!$E:$E,'VẬT TƯ'!B13,'NHẬP LIỆU'!$L:$L) -> 566.62875 | H13: =+E13+F13-G13 -> 110.19125 | I13: (1c = 4,4kg) | K13: =+'VẬT TƯ'!$H13/4.4 -> 25.043466
A14: =+ROW()-3 -> 11 | B14: KRAFT | C14: Kraft nâu LG (cuộn) | D14: Kg | E14: 0 | F14: =+SUMIF('NHẬP LIỆU'!$E:$E,'VẬT TƯ'!B14,'NHẬP LIỆU'!$K:$K) -> 1562 | G14: =+SUMIF('NHẬP LIỆU'!$E:$E,'VẬT TƯ'!B14,'NHẬP LIỆU'!$L:$L) -> 1084 | H14: =+E14+F14-G14 -> 478 | I14: 65+413
A15: =+ROW()-3 -> 12 | B15: GIAYBAOLG | C15: Giấy bao gói lưỡi gà | D15: Kg | E15: 0 | F15: =+SUMIF('NHẬP LIỆU'!$E:$E,'VẬT TƯ'!B15,'NHẬP LIỆU'!$K:$K) -> 1157 | G15: =+SUMIF('NHẬP LIỆU'!$E:$E,'VẬT TƯ'!B15,'NHẬP LIỆU'!$L:$L) -> 808.53997 | H15: =+E15+F15-G15 -> 348.46003
A16: =+ROW()-3 -> 13 | B16: DAY.DAI.PET | C16: Dây đai PET xanh (B) | D16: Kg | E16: 112.31 | F16: =+SUMIF('NHẬP LIỆU'!$E:$E,'VẬT TƯ'!B16,'NHẬP LIỆU'!$K:$K) -> 700 | G16: =+SUMIF('NHẬP LIỆU'!$E:$E,'VẬT TƯ'!B16,'NHẬP LIỆU'!$L:$L) -> 781.37206 | H16: =+E16+F16-G16 -> 30.93794 | I16: (1c=20kg) | K16: =+'VẬT TƯ'!$H16/20 -> 1.546897
A17: =+ROW()-3 -> 14 | B17: GIAYLOTDG | C17: Giấy lót đóng gói | D17: Kg | E17: 0 | F17: =+SUMIF('NHẬP LIỆU'!$E:$E,'VẬT TƯ'!B17,'NHẬP LIỆU'!$K:$K) -> 990.55 | G17: =+SUMIF('NHẬP LIỆU'!$E:$E,'VẬT TƯ'!B17,'NHẬP LIỆU'!$L:$L) -> 324 | H17: =+E17+F17-G17 -> 666.55

Sheet NKSX
A2: NKSX | P2: =+SUBTOTAL(9,$P$5:$P$490) -> 767430.98
A3: STT | B3: NGÀY CẮT | C3: Số ĐH | D3: LSX | E3: Khách | F3: MÃ NVL | G3: Loại Giấy | H3: NVL | K3: MÃ TP | L3: TP | Q3: BTP | T3: Bao bì (kg) | U3: Nòng Ống | W3: Giấy phế(Kg) | X3: Cuộn dở(Kg) | Y3: Hao hụt (kg) | AC3: Vật Tư | AK3: Thợ cắt | AL3: Ngày hoàn thành | AM3: Ghi Chú
H4: ĐL (Gsm) | I4: Khổ (cm) | J4: Trọng Lượng (kg) | L4: ĐL (Gsm) | M4: Khổ (mm) | N4: dài (m) | O4: Số Cuộn | P4: Trọng Lượng (kg) | Q4: dài (m) | R4: Số Cuộn | S4: Trọng Lượng (kg) | U4: Trọng lượng (kg) | V4: Số lượng (cái) | Y4: Hao hụt (kg) | Z4: Tổng hao hụt(Kg) | AA4: % Hao Hụt | AB4: Hiệu Suất | AC4: Kích Thước pallet | AD4: số lượng (cái) | AE4: Nẹp Gỗ | AF4: Ống giấy (cái) | AG4: Màng Pe (kg) | AH4: Dây đai pet (kg) | AI4: Giấy bao gói (kg) | AJ4: Giấy lot ĐG (kg)
A5: =+ROW()-4 -> 1 | B5: 45499 | C5: 01.07/LGT-BBMN | D5: 39/2024 | E5: BBMN | F5: INIB250109 | G5: =+IFERROR(VLOOKUP(F5,NVL!$B:$C,2,0),"") -> Ivory Ningbo | H5: =+IFERROR(VLOOKUP(F5,NVL!$B:$D,3,0),"") -> 250 | I5: =+IFERROR(VLOOKUP(F5,NVL!$B:$F,4,0),"") -> 109 | J5: =3*981 -> 2943 | K5: LGT250/90-TS | L5: =+IFERROR(VLOOKUP(K5,'THÀNH PHẨM'!$B:$F,3,0),"") -> 250 | M5: =+IFERROR(VLOOKUP(K5,'THÀNH PHẨM'!$B:$F,4,0),"") -> 90 | N5: =+IFERROR(VLOOKUP(K5,'THÀNH PHẨM'!$B:$F,5,0),"") -> 800 | O5: 162 | P5: =+IFERROR(((L5*M5*N5)*O5/1000000),"") -> 2916 | S5: =+IFERROR(((L5*M5*Q5)*R5/1000000),"") -> 0 | T5: 6 | U5: 18 | V5: 3 | W5: 27 | Y5: =+IF(J5="","",J5-P5-S5-W5-X5) -> 0 | Z5: =+IF(J5<>"",Y5+W5,0) -> 27 | AA5: =+IF(IF(J5=";",Z5/J5)<0,0%,(IF(J5="","",Z5/J5))) -> 0.0091743119 | AK5: Vinh | AL5: 45506
A6: =+ROW()-4 -> 2 | B6: 45499 | C6: 01.07/LGT-BBMN | D6: 39/2024 | E6: BBMN | F6: INIB25065 | G6: =+IFERROR(VLOOKUP(F6,NVL!$B:$C,2,0),"") -> Ivory Ningbo | H6: =+IFERROR(VLOOKUP(F6,NVL!$B:$D,3,0),"") -> 250 | I6: =+IFERROR(VLOOKUP(F6,NVL!$B:$F,4,0),"") -> 65 | J6: =6*585 -> 3510 | K6: LGT250/90-TS | L6: =+IFERROR(VLOOKUP(K6,'THÀNH PHẨM'!$B:$F,3,0),"") -> 250 | M6: =+IFERROR(VLOOKUP(K6,'THÀNH PHẨM'!$B:$F,4,0),"") -> 90 | N6: =+IFERROR(VLOOKUP(K6,'THÀNH PHẨM'!$B:$F,5,0),"") -> 800 | O6: 181 | P6: =+IFERROR(((L6*M6*N6)*O6/1000000),"") -> 3258 | Q6: 420 | R6: 1 | S6: =+IFERROR(((L6*M6*Q6)*R6/1000000),"") -> 9.45 | T6: 12 | U6: 36 | V6: 6 | W6: 212.85 | Y6: =+IF(J6="","",J6-P6-S6-W6-X6-S7) -> 0 | Z6: =+IF(J6<>"",Y6+W6,0) -> 212.85 | AA6: =+IF(IF(J6=";",Z6/J6)<0,0%,(IF(J6="","",Z6/J6))) -> 0.060641026 | AK6: Vinh | AL6: 45506
A7: =+ROW()-4 -> 3 | B7: 45499 | C7: 01.07/LGT-BBMN | D7: 39/2024 | E7: BBMN | F7: INIB25065 | G7: =+IFERROR(VLOOKUP(F7,NVL!$B:$C,2,0),"") -> Ivory Ningbo | H7: =+IFERROR(VLOOKUP(F7,NVL!$B:$D,3,0),"") -> 250 | I7: =+IFERROR(VLOOKUP(F7,NVL!$B:$F,4,0),"") -> 65 | K7: LGT250/90-TS | L7: =+IFERROR(VLOOKUP(K7,'THÀNH PHẨM'!$B:$F,3,0),"") -> 250 | M7: =+IFERROR(VLOOKUP(K7,'THÀNH PHẨM'!$B:$F,4,0),"") -> 90 | N7: =+IFERROR(VLOOKUP(K7,'THÀNH PHẨM'!$B:$F,5,0),"") -> 800 | P7: =+IFERROR(((L7*M7*N7)*O7/1000000),"") -> 0 | Q7: 330 | R7: 4 | S7: =+IFERROR(((L7*M7*Q7)*R7/1000000),"") -> 29.7 | AK7: Vinh | AL7: 45506
A8: =+ROW()-4 -> 4 | B8: 45499 | C8: 01.07/LGT-BBMN | D8: 39/2024 | E8: BBMN | F8: INIB25075 | G8: =+IFERROR(VLOOKUP(F8,NVL!$B:$C,2,0),"") -> Ivory Ningbo | H8: =+IFERROR(VLOOKUP(F8,NVL!$B:$D,3,0),"") -> 250 | I8: =+IFERROR(VLOOKUP(F8,NVL!$B:$F,4,0),"") -> 75 | J8: =675*5 -> 3375 | K8: LGT250/90-TS | L8: =+IFERROR(VLOOKUP(K8,'THÀNH PHẨM'!$B:$F,3,0),"") -> 250 | M8: =+IFERROR(VLOOKUP(K8,'THÀNH PHẨM'!$B:$F,4,0),"") -> 90 | N8: =+IFERROR(VLOOKUP(K8,'THÀNH PHẨM'!$B:$F,5,0),"") -> 800 | O8: 180 | P8: =+IFERROR(((L8*M8*N8)*O8/1000000),"") -> 3240 | S8: =+IFERROR(((L8*M8*Q8)*R8/1000000),"") -> 0 | T8: 10 | U8: 30 | V8: 5 | W8: 135 | Y8: =+IF(J8="","",J8-P8-S8-W8-X8) -> 0 | Z8: =+IF(J8<>"",Y8+W8,0) -> 135 | AA8: =+IF(IF(J8=";",Z8/J8)<0,0%,(IF(J8="","",Z8/J8))) -> 0.04 | AK8: Vinh | AL8: 45506
A9: =+ROW()-4 -> 5 | B9: 45499 | C9: 01.07/LGT-BBMN | D9: 39/2024 | E9: BBMN | F9: IIPS25084 | G9: =+IFERROR(VLOOKUP(F9,NVL!$B:$C,2,0),"") -> Ivory IPSUN | H9: =+IFERROR(VLOOKUP(F9,NVL!$B:$D,3,0),"") -> 250 | I9: =+IFERROR(VLOOKUP(F9,NVL!$B:$F,4,0),"") -> 84 | J9: 128 | K9: LGT250/90-TS | L9: =+IFERROR(VLOOKUP(K9,'THÀNH PHẨM'!$B:$F,3,0),"") -> 250 | M9: =+IFERROR(VLOOKUP(K9,'THÀNH PHẨM'!$B:$F,4,0),"") -> 90 | N9: =+IFERROR(VLOOKUP(K9,'THÀNH PHẨM'!$B:$F,5,0),"") -> 800 | O9: 5 | P9: =+IFERROR(((L9*M9*N9)*O9/1000000),"") -> 90 | S9: =+IFERROR(((L9*M9*Q9)*R9/1000000),"") -> 0 | T9: 1 | W9: 8 | X9: 30 | Y9: =+IF(J9="","",J9-P9-S9-W9-X9) -> 0 | Z9: =+IF(J9<>"",Y9+W9,0) -> 8 | AA9: =+IF(IF(J9=";",Z9/J9)<0,0%,(IF(J9="","",Z9/J9))) -> 0.0625 | AK9: Vinh | AL9: 45506
A10: =+ROW()-4 -> 6 | B10: 45511 | C10: 24/LGT/08 | D10: 40/2024 | E10: TLTL | F10: IIPS230109 | G10: =+IFERROR(VLOOKUP(F10,NVL!$B:$C,2,0),"") -> Ivory IPSUN | H10: =+IFERROR(VLOOKUP(F10,NVL!$B:$D,3,0),"") -> 230 | I10: =+IFERROR(VLOOKUP(F10,NVL!$B:$F,4,0),"") -> 109 | J10: =6*1028+912 -> 7080 | K10: LGT230/98-TS | L10: =+IFERROR(VLOOKUP(K10,'THÀNH PHẨM'!$B:$F,3,0),"") -> 230 | M10: =+IFERROR(VLOOKUP(K10,'THÀNH PHẨM'!$B:$F,4,0),"") -> 98 | N10: =+IFERROR(VLOOKUP(K10,'THÀNH PHẨM'!$B:$F,5,0),"") -> 800 | O10: 363 | P10: =+IFERROR(((L10*M10*N10)*O10/1000000),"") -> 6545.616 | S10: =+IFERROR(((L10*M10*Q10)*R10/1000000),"") -> 0 | T10: 10 | U10: 36 | V10: 6 | W10: 107.38 | X10: 427 | Y10: =+IF(J10="","",J10-P10-S10-W10-X10) -> 0.004 | Z10: =+IF(J10<>"",Y10+W10,0) -> 107.384 | AA10: =+IF(IF(J10=";",Z10/J10)<0,0%,(IF(J10="","",Z10/J10))) -> 0.015167232 | AK10: Vinh | AL10: 45517
A11: =+ROW()-4 -> 7 | B11: 45516 | C11: Hàng mẫu | D11: 41/2024 | E11: VPMN | F11: INIB23065 | G11: =+IFERROR(VLOOKUP(F11,NVL!$B:$C,2,0),"") -> Ivory Ningbo | H11: =+IFERROR(VLOOKUP(F11,NVL!$B:$D,3,0),"") -> 230 | I11: =+IFERROR(VLOOKUP(F11,NVL!$B:$F,4,0),"") -> 65 | J11: 30 | K11: LGT23090 | L11: 230 | M11: 90 | N11: 200 | O11: 2 | P11: =+IFERROR(((L11*M11*N11)*O11/1000000),"") -> 8.28 | S11: =+IFERROR(((L11*M11*Q11)*R11/1000000),"") -> 0 | W11: 4.1 | Y11: =+IF(J11="","",J11-P11-S11-W11-X11-P12-P13) -> 0.002 | Z11: =+IF(J11<>"",Y11+W11,0) -> 4.102 | AA11: =+IF(IF(J11=";",Z11/J11)<0,0%,(IF(J11="","",Z11/J11))) -> 0.13673333 | AK11: Vinh | AL11: 45517
A12: =+ROW()-4 -> 8 | B12: 45516 | C12: Hàng mẫu | D12: 41/2024 | E12: VPMN | K12: LGT23095 | L12: 230 | M12: 95 | N12: 200 | O12: 2 | P12: =+IFERROR(((L12*M12*N12)*O12/1000000),"") -> 8.74 | S12: =+IFERROR(((L12*M12*Q12)*R12/1000000),"") -> 0 | AK12: Vinh | AL12: 45517
A13: =+ROW()-4 -> 9 | B13: 45516 | C13: Hàng mẫu | D13: 41/2024 | E13: VPMN | K13: LGT23096.5 | L13: 230 | M13: 96.5 | N13: 200 | O13: 2 | P13: =+IFERROR(((L13*M13*N13)*O13/1000000),"") -> 8.878 | S13: =+IFERROR(((L13*M13*Q13)*R13/1000000),"") -> 0 | AK13: Vinh | AL13: 45517
A14: =+ROW()-4 -> 10 | B14: 45519 | C14: 01.07/LGT-BBMN (95mm), 24/LGT/08 (71mm), Hàng mẫu (83mm) | D14: 42/2024 | E14: TLBT | F14: IIPS210109 | G14: =+IFERROR(VLOOKUP(F14,NVL!$B:$C,2,0),"") -> Ivory IPSUN | H14: =+IFERROR(VLOOKUP(F14,NVL!$B:$D,3,0),"") -> 210 | I14: =+IFERROR(VLOOKUP(F14,NVL!$B:$F,4,0),"") -> 109 | J14: =1053*5+655+63 -> 5983 | K14: LGT210/95-TS | L14: =+IFERROR(VLOOKUP(K14,'THÀNH PHẨM'!$B:$F,3,0),"") -> 210 | M14: =+IFERROR(VLOOKUP(K14,'THÀNH PHẨM'!$B:$F,4,0),"") -> 95 | N14: =+IFERROR(VLOOKUP(K14,'THÀNH PHẨM'!$B:$F,5,0),"") -> 800 | O14: 286 | P14: =+IFERROR(((L14*M14*N14)*O14/1000000),"") -> 4564.56 | S14: =+IFERROR(((L14*M14*Q14)*R14/1000000),"") -> 0 | T14: 14 | U14: 36 | V14: 6 | W14: 160.84 | X14: 48 | Y14: =+IF(J14="","",J14-P14-S14-W14-X14-P15-P16) -> 0 | Z14: =+IF(J14<>"",Y14+W14,0) -> 160.84 | AA14: =+IF(IF(J14=";",Z14/J14)<0,0%,(IF(J14="","",Z14/J14))) -> 0.026882835 | AK14: Vinh | AL14: 45523
A15: =+ROW()-4 -> 11 | B15: 45519 | C15: 01.07/LGT-BBMN (95mm), 24/LGT/08 (71mm), Hàng mẫu (83mm) | D15: 42/2024 | E15: TLTL | K15: LGT210/83-TS | L15: =+IFERROR(VLOOKUP(K15,'THÀNH PHẨM'!$B:$F,3,0),"") -> 210 | M15: =+IFERROR(VLOOKUP(K15,'THÀNH PHẨM'!$B:$F,4,0),"") -> 83 | N15: =+IFERROR(VLOOKUP(K15,'THÀNH PHẨM'!$B:$F,5,0),"") -> 800 | O15: 32 | P15: =+IFERROR(((L15*M15*N15)*O15/1000000),"") -> 446.208 | S15: =+IFERROR(((L15*M15*Q15)*R15/1000000),"") -> 0 | AK15: Vinh | AL15: 45523
A16: =+ROW()-4 -> 12 | B16: 45519 | C16: 01.07/LGT-BBMN (95mm), 24/LGT/08 (71mm), Hàng mẫu (83mm) | D16: 42/2024 | E16: TLTL | K16: LGT210/71-TS | L16: =+IFERROR(VLOOKUP(K16,'THÀNH PHẨM'!$B:$F,3,0),"") -> 210 | M16: =+IFERROR(VLOOKUP(K16,'THÀNH PHẨM'!$B:$F,4,0),"") -> 71 | N16: =+IFERROR(VLOOKUP(K16,'THÀNH PHẨM'!$B:$F,5,0),"") -> 800 | O16: 64 | P16: =+IFERROR(((L16*M16*N16)*O16/1000000),"") -> 763.392 | S16: =+IFERROR(((L16*M16*Q16)*R16/1000000),"") -> 0 | AK16: Vinh | AL16: 45523
A17: =+ROW()-4 -> 13 | B17: 45524 | C17: 01.08/LGT-BBMN | D17: 43/2024 | E17: BBMN | F17: INIB250102 | G17: =+IFERROR(VLOOKUP(F17,NVL!$B:$C,2,0),"") -> Ivory Ningbo | H17: =+IFERROR(VLOOKUP(F17,NVL!$B:$D,3,0),"") -> 250 | I17: =+IFERROR(VLOOKUP(F17,NVL!$B:$F,4,0),"") -> 102 | J17: =918*6 -> 5508 | K17: LGT250/90-TS | L17: =+IFERROR(VLOOKUP(K17,'THÀNH PHẨM'!$B:$F,3,0),"") -> 250 | M17: =+IFERROR(VLOOKUP(K17,'THÀNH PHẨM'!$B:$F,4,0),"") -> 90 | N17: =+IFERROR(VLOOKUP(K17,'THÀNH PHẨM'!$B:$F,5,0),"") -> 800 | O17: 286 | P17: =+IFERROR(((L17*M17*N17)*O17/1000000),"") -> 5148 | S17: =+IFERROR(((L17*M17*Q17)*R17/1000000),"") -> 0 | T17: 14 | U17: 36 | V17: 6 | W17: 203 | X17: 157 | Y17: =+IF(J17="","",J17-P17-S17-W17-X17) -> 0 | Z17: =+IF(J17<>"",Y17+W17,0) -> 203 | AA17: =+IF(IF(J17=";",Z17/J17)<0,0%,(IF(J17="","",Z17/J17))) -> 0.036855483 | AK17: Vinh | AL17: 45526
A18: =+ROW()-4 -> 14 | B18: 45528 | C18: 02.08/LGT-BBMN (520 cuộn) và 01.09/LGT-BBMN (1040 cuộn) | D18: 44/2024 | E18: BBMN | F18: INIB250102 | G18: =+IFERROR(VLOOKUP(F18,NVL!$B:$C,2,0),"") -> Ivory Ningbo | H18: =+IFERROR(VLOOKUP(F18,NVL!$B:$D,3,0),"") -> 250 | I18: =+IFERROR(VLOOKUP(F18,NVL!$B:$F,4,0),"") -> 102 | J18: 157 | K18: LGT250/90-TS | L18: =+IFERROR(VLOOKUP(K18,'THÀNH PHẨM'!$B:$F,3,0),"") -> 250 | M18: =+IFERROR(VLOOKUP(K18,'THÀNH PHẨM'!$B:$F,4,0),"") -> 90 | N18: =+IFERROR(VLOOKUP(K18,'THÀNH PHẨM'!$B:$F,5,0),"") -> 800 | P18: =+IFERROR(((L18*M18*N18)*O18/1000000),"") -> 0 | Q18: 420 | R18: 11 | S18: =+IFERROR(((L18*M18*Q18)*R18/1000000),"") -> 103.95 | T18: 2 | U18: 7 | V18: 1 | W18: 53.05 | Y18: =+IF(J18="","",J18-P18-S18-W18-X18) -> 0 | Z18: =+IF(J18<>"",Y18+W18,0) -> 53.05 | AA18: =+IF(IF(J18=";",Z18/J18)<0,0%,(IF(J18="","",Z18/J18))) -> 0.33789809 | AK18: Vinh | AL18: 45547
A19: =+ROW()-4 -> 15 | B19: 45528 | C19: 02.08/LGT-BBMN (520 cuộn) và 01.09/LGT-BBMN (1040 cuộn) | D19: 44/2024 | E19: BBMN | F19: INIB250100 | G19: =+IFERROR(VLOOKUP(F19,NVL!$B:$C,2,0),"") -> Ivory Ningbo | H19: =+IFERROR(VLOOKUP(F19,NVL!$B:$D,3,0),"") -> 250 | I19: =+IFERROR(VLOOKUP(F19,NVL!$B:$F,4,0),"") -> 100 | J19: =19*900 -> 17100 | K19: LGT250/90-TS | L19: =+IFERROR(VLOOKUP(K19,'THÀNH PHẨM'!$B:$F,3,0),"") -> 250 | M19: =+IFERROR(VLOOKUP(K19,'THÀNH PHẨM'!$B:$F,4,0),"") -> 90 | N19: =+IFERROR(VLOOKUP(K19,'THÀNH PHẨM'!$B:$F,5,0),"") -> 800 | O19: 935 | P19: =+IFERROR(((L19*M19*N19)*O19/1000000),"") -> 16830 | S19: =+IFERROR(((L19*M19*Q19)*R19/1000000),"") -> 0 | T19: 38 | U19: =18*7 -> 126 | V19: 18 | W19: 187 | X19: 83 | Y19: =+IF(J19="","",J19-P19-S19-W19-X19) -> 0 | Z19: =+IF(J19<>"",Y19+W19,0) -> 187 | AA19: =+IF(IF(J19=";",Z19/J19)<0,0%,(IF(J19="","",Z19/J19))) -> 0.010935673 | AK19: Vinh | AL19: 45547
A20: =+ROW()-4 -> 16 | B20: 45548 | C20: 24/LGT/08 | D20: 45/2024 | E20: TLTL | F20: INIB21086 | G20: =+IFERROR(VLOOKUP(F20,NVL!$B:$C,2,0),"") -> Ivory Ningbo | H20: =+IFERROR(VLOOKUP(F20,NVL!$B:$D,3,0),"") -> 210 | I20: =+IFERROR(VLOOKUP(F20,NVL!$B:$F,4,0),"") -> 86 | J20: =7*813 -> 5691 | K20: LGT210/71-TS | L20: =+IFERROR(VLOOKUP(K20,'THÀNH PHẨM'!$B:$F,3,0),"") -> 210 | M20: =+IFERROR(VLOOKUP(K20,'THÀNH PHẨM'!$B:$F,4,0),"") -> 71 | N20: =+IFERROR(VLOOKUP(K20,'THÀNH PHẨM'!$B:$F,5,0),"") -> 800 | O20: 419 | P20: =+IFERROR(((L20*M20*N20)*O20/1000000),"") -> 4997.832 | Q20: 400 | R20: 12 | S20: =IFERROR(((H20*M20*R20/1000000)*Q20),"") -> 71.568 | T20: 14 | U20: 42 | V20: 6 | W20: 81.6 | X20: 540 | Y20: =+IF(J20="","",J20-P20-S20-W20-X20) -> 0 | Z20: =+IF(J20<>"",Y20+W20,0) -> 81.6 | AA20: =+IF(IF(J20=";",Z20/J20)<0,0%,(IF(J20="","",Z20/J20))) -> 0.014338429 | AK20: Vinh | AL20: 45553
A21: =+ROW()-4 -> 17 | B21: 45553 | C21: 01.09/LGT-BBMN (1040 cuộn | D21: 46/2024 | E21: TLSG | F21: INIB250109 | G21: =+IFERROR(VLOOKUP(F21,NVL!$B:$C,2,0),"") -> Ivory Ningbo | H21: =+IFERROR(VLOOKUP(F21,NVL!$B:$D,3,0),"") -> 250 | I21: =+IFERROR(VLOOKUP(F21,NVL!$B:$F,4,0),"") -> 109 | J21: =9*981 -> 8829 | K21: LGT250/90-TS | L21: =+IFERROR(VLOOKUP(K21,'THÀNH PHẨM'!$B:$F,3,0),"") -> 250 | M21: =+IFERROR(VLOOKUP(K21,'THÀNH PHẨM'!$B:$F,4,0),"") -> 90 | N21: =+IFERROR(VLOOKUP(K21,'THÀNH PHẨM'!$B:$F,5,0),"") -> 800 | O21: 463 | P21: =+IFERROR(((L21*M21*N21)*O21/1000000),"") -> 8334 | Q21: 800 | R21: 5 | S21: =IFERROR(((H21*M21*R21/1000000)*Q21),"") -> 90 | T21: 18 | U21: 56 | V21: 8 | W21: 195 | X21: 210 | Y21: =+IF(J21="","",J21-P21-S21-W21-X21) -> 0 | Z21: =+IF(J21<>"",Y21+W21,0) -> 195 | AA21: =+IF(IF(J21=";",Z21/J21)<0,0%,(IF(J21="","",Z21/J21))) -> 0.022086306 | AK21: Vinh | AL21: 45559
A22: =+ROW()-4 -> 18 | B22: 45560 | C22: 24/LGT/08 và 02.09/LGT-BBMN | D22: 47/2024 | E22: TLBT | F22: IIPS210109 | G22: =+IFERROR(VLOOKUP(F22,NVL!$B:$C,2,0),"") -> Ivory IPSUN | H22: =+IFERROR(VLOOKUP(F22,NVL!$B:$D,3,0),"") -> 210 | I22: =+IFERROR(VLOOKUP(F22,NVL!$B:$F,4,0),"") -> 109 | J22: =1053*4 -> 4212 | K22: LGT210/95-TS | L22: =+IFERROR(VLOOKUP(K22,'THÀNH PHẨM'!$B:$F,3,0),"") -> 210 | M22: =+IFERROR(VLOOKUP(K22,'THÀNH PHẨM'!$B:$F,4,0),"") -> 95 | N22: =+IFERROR(VLOOKUP(K22,'THÀNH PHẨM'!$B:$F,5,0),"") -> 800 | O22: 173 | P22: =+IFERROR(((L22*M22*N22)*O22/1000000),"") -> 2761.08 | Q22: 800 | R22: 12 | S22: 191.52 | T22: 8 | U22: 21 | V22: 3 | W22: 122.17 | X22: 200 | Y22: =+IF(J22="","",J22-P22-S22-W22-X22-P23-P24-P25-S23) -> 0 | Z22: =+IF(J22<>"",Y22+W22,0) -> 122.17 | AA22: =+IF(IF(J22=";",Z22/J22)<0,0%,(IF(J22="","",Z22/J22))) -> 0.029005223 | AK22: Vinh | AL22: 45565
A23: =+ROW()-4 -> 19 | D23: 47/2024 | E23: TLBT | K23: LGT210/95-TS | L23: =+IFERROR(VLOOKUP(K23,'THÀNH PHẨM'!$B:$F,3,0),"") -> 210 | M23: =+IFERROR(VLOOKUP(K23,'THÀNH PHẨM'!$B:$F,4,0),"") -> 95 | N23: =+IFERROR(VLOOKUP(K23,'THÀNH PHẨM'!$B:$F,5,0),"") -> 800 | P23: =+IFERROR(((L23*M23*N23)*O23/1000000),"") -> 0 | Q23: 600 | R23: 7 | S23: 83.79 | AK23: Vinh | AL23: 45565
A24: =+ROW()-4 -> 20 | D24: 47/2024 | E24: TLTL | K24: LGT210/71-TS | L24: =+IFERROR(VLOOKUP(K24,'THÀNH PHẨM'!$B:$F,3,0),"") -> 210 | M24: =+IFERROR(VLOOKUP(K24,'THÀNH PHẨM'!$B:$F,4,0),"") -> 71 | N24: =+IFERROR(VLOOKUP(K24,'THÀNH PHẨM'!$B:$F,5,0),"") -> 800 | O24: 47 | P24: =+IFERROR(((L24*M24*N24)*O24/1000000),"") -> 560.616 | S24: 0 | AK24: Vinh | AL24: 45565
A25: =+ROW()-4 -> 21 | D25: 47/2024 | E25: TLTL | K25: LGT210/83-TS | L25: =+IFERROR(VLOOKUP(K25,'THÀNH PHẨM'!$B:$F,3,0),"") -> 210 | M25: =+IFERROR(VLOOKUP(K25,'THÀNH PHẨM'!$B:$F,4,0),"") -> 83 | N25: =+IFERROR(VLOOKUP(K25,'THÀNH PHẨM'!$B:$F,5,0),"") -> 800 | O25: 21 | P25: =+IFERROR(((L25*M25*N25)*O25/1000000),"") -> 292.824 | S25: 0 | AK25: Vinh | AL25: 45565
A26: =+ROW()-4 -> 22 | B26: 45566 | C26: 03.09/LGT-BBMN | D26: 48/2024 | E26: TLBT | F26: INIB21086 | G26: =+IFERROR(VLOOKUP(F26,NVL!$B:$C,2,0),"") -> Ivory Ningbo | H26: =+IFERROR(VLOOKUP(F26,NVL!$B:$D,3,0),"") -> 210 | I26: =+IFERROR(VLOOKUP(F26,NVL!$B:$F,4,0),"") -> 86 | J26: =813*5+540 -> 4605 | K26: LGT210/95-TS | L26: =+IFERROR(VLOOKUP(K26,'THÀNH PHẨM'!$B:$F,3,0),"") -> 210 | M26: =+IFERROR(VLOOKUP(K26,'THÀNH PHẨM'!$B:$F,4,0),"") -> 95 | N26: =+IFERROR(VLOOKUP(K26,'THÀNH PHẨM'!$B:$F,5,0),"") -> 800 | O26: 279 | P26: =+IFERROR(((L26*M26*N26)*O26/1000000),"") -> 4452.84 | S26: =+IFERROR(((L26*M26*Q26)*R26/1000000),"") -> 0 | T26: 12 | U26: 30 | V26: 5 | W26: 102.16 | X26: 50 | Y26: =+IF(J26="","",J26-P26-S26-W26-X26) -> 0 | Z26: =+IF(J26<>"",Y26+W26,0) -> 102.16 | AA26: =+IF(IF(J26=";",Z26/J26)<0,0%,(IF(J26="","",Z26/J26))) -> 0.022184582 | AK26: Vinh | AL26: 45569
A27: =+ROW()-4 -> 23 | B27: 45568 | C27: 24/LGT/08 | D27: 49/2024 | E27: TLTL | F27: INIB21086 | G27: =+IFERROR(VLOOKUP(F27,NVL!$B:$C,2,0),"") -> Ivory Ningbo | H27: =+IFERROR(VLOOKUP(F27,NVL!$B:$D,3,0),"") -> 210 | I27: =+IFERROR(VLOOKUP(F27,NVL!$B:$F,4,0),"") -> 86 | J27: =+ 813*2+50 -> 1676 | K27: LGT210/71-TS | L27: =+IFERROR(VLOOKUP(K27,'THÀNH PHẨM'!$B:$F,3,0),"") -> 210 | M27: =+IFERROR(VLOOKUP(K27,'THÀNH PHẨM'!$B:$F,4,0),"") -> 71 | N27: =+IFERROR(VLOOKUP(K27,'THÀNH PHẨM'!$B:$F,5,0),"") -> 800 | O27: 92 | P27: =+IFERROR(((L27*M27*N27)*O27/1000000),"") -> 1097.376 | S27: =+IFERROR(((L27*M27*Q27)*R27/1000000),"") -> 0 | T27: 6 | U27: 14 | V27: 2 | W27: 14.98 | X27: 105 | Y27: =+IF(J27="","",J27-P27-S27-W27-X27-P28) -> 0.004 | Z27: =+IF(J27<>"",Y27+W27,0) -> 14.984 | AA27: =+IF(IF(J27=";",Z27/J27)<0,0%,(IF(J27="","",Z27/J27))) -> 0.0089403341 | AK27: Vinh | AL27: 45572
A28: =+ROW()-4 -> 24 | B28: 45568 | C28: 24/LGT/11 | D28: 49/2024 | E28: TLTL | K28: LGT210/91-TS | L28: =+IFERROR(VLOOKUP(K28,'THÀNH PHẨM'!$B:$F,3,0),"") -> 210 | M28: =+IFERROR(VLOOKUP(K28,'THÀNH PHẨM'!$B:$F,4,0),"") -> 91 | N28: =+IFERROR(VLOOKUP(K28,'THÀNH PHẨM'!$B:$F,5,0),"") -> 800 | O28: 30 | P28: =+IFERROR(((L28*M28*N28)*O28/1000000),"") -> 458.64 | S28: =+IFERROR(((L28*M28*Q28)*R28/1000000),"") -> 0 | AK28: Vinh | AL28: 45572
A29: =+ROW()-4 -> 25 | B29: 45573 | C29: 24/LGT/08 và 24/LGT/10 | D29: 50/2024 | E29: TLTL | F29: INIB21079 | G29: =+IFERROR(VLOOKUP(F29,NVL!$B:$C,2,0),"") -> Ivory Ningbo | H29: =+IFERROR(VLOOKUP(F29,NVL!$B:$D,3,0),"") -> 210 | I29: =+IFERROR(VLOOKUP(F29,NVL!$B:$F,4,0),"") -> 79 | J29: =16*747+2*713+6*747 -> 17860 | K29: LGT210/71-TS | L29: =+IFERROR(VLOOKUP(K29,'THÀNH PHẨM'!$B:$F,3,0),"") -> 210 | M29: =+IFERROR(VLOOKUP(K29,'THÀNH PHẨM'!$B:$F,4,0),"") -> 71 | N29: =+IFERROR(VLOOKUP(K29,'THÀNH PHẨM'!$B:$F,5,0),"") -> 800 | O29: =1440-29 -> 1411 | P29: =+IFERROR(((L29*M29*N29)*O29/1000000),"") -> 16830.408 | S29: =+IFERROR(((L29*M29*Q29)*R29/1000000),"") -> 0 | T29: 48 | U29: 144 | V29: 24 | W29: 434.59 | X29: 700 | Y29: =+IF(J29="","",J29+J30-P29-S29-W29-X29) -> 0.002 | Z29: =+IF(J29<>"",Y29+W29,0) -> 434.592 | AA29: =+IF(IF(J29=";",Z29/J29)<0,0%,(IF(J29="","",Z29/J29))) -> 0.024333259 | AK29: Vinh | AL29: 45591
