Workbook

Sheet SỔ CHI TIẾT BÁN HÀNG
G2: =SUBTOTAL(9,G5:G6341) -> 24589148 | J2: =SUBTOTAL(9,J5:J6341) -> 4115863132 | K2: =SUBTOTAL(9,K5:K6341) -> 55688607163 | Q2: =SUBTOTAL(9,Q5:Q6341) -> 24588958
A3: BÁN RA | O3: MUA HÀNG AVP
A4: Ngày hóa đơn | B4: Số hóa đơn | C4: Mã hàng | D4: Tên hàng trên chứng từ | E4: Tên khách hàng | F4: ĐVT | G4: Tổng số lượng bán | H4: Đơn giá | I4: Doanh số bán | J4: Thuế GTGT | K4: Tổng thanh toán | M4: DD khach | N4: Số đơn đặt hàng mua TS-AVP | O4: Ngày hóa đơn | P4: Số hóa đơn | Q4: Tổng số lượng mua | R4: Đơn giá | S4: Doanh số bán | T4: Thuế GTGT | U4: Tổng thanh toán
A5: 46028 | B5: 00000006 | C5: HH-CT00007 | D5: Thùng carton SAIGON Silver DS-TĐ | E5: CÔNG TY TNHH MỘT THÀNH VIÊN THUỐC LÁ SÀI GÒN | F5: Cái | G5: 7000 | H5: 18291 | I5: 128037000 | J5: 10242960 | K5: 138279960 | L5: 11-10-TS137-2025/TS-AVP/ĐĐHHH-CT00007 | M5: =VLOOKUP(L5,'Đơn đặt'!$C$3:$E$275,2,0) -> 11-10-TS | N5: =VLOOKUP(L5,'Đơn đặt'!$C$3:$E$275,3,0) -> 137-2025/TS-AVP/ĐĐH | O5: 46027 | P5: 00000009 | Q5: 7000 | R5: 14018.2 | S5: 98127400 | T5: 7850192 | U5: =S5+T5 -> 105977592
A6: 46028 | B6: 00000007 | C6: HH-CT00064 | D6: Thùng carton GREENHILL 100SP MENTHOL | E6: CÔNG TY TNHH MỘT THÀNH VIÊN THUỐC LÁ SÀI GÒN | F6: Cái | G6: 2000 | H6: 21777 | I6: 43554000 | J6: 3484320 | K6: 47038320 | L6: 12-09-TS149-2025/TS-AVP/ĐĐHHH-CT00064 | M6: =VLOOKUP(L6,'Đơn đặt'!$C$3:$E$275,2,0) -> 12-09-TS | N6: =VLOOKUP(L6,'Đơn đặt'!$C$3:$E$275,3,0) -> 149-2025/TS-AVP/ĐĐH | O6: 46027 | P6: 00000017 | Q6: 2000 | R6: 19059.4 | S6: 38118800 | T6: 3049504 | U6: =S6+T6 -> 41168304
A7: 46028 | B7: 00000008 | C7: HH-CT00078 | D7: Thùng carton MELIA Ment BC-TĐ | E7: CÔNG TY TNHH MỘT THÀNH VIÊN THUỐC LÁ SÀI GÒN | F7: Cái | G7: 1200 | H7: 20024 | I7: 24028800 | J7: 1922304 | K7: 25951104 | L7: 12-01-TS03-2026/TS-AVP/ĐĐHHH-CT00078 | M7: =VLOOKUP(L7,'Đơn đặt'!$C$3:$E$275,2,0) -> 12-01-TS | N7: =VLOOKUP(L7,'Đơn đặt'!$C$3:$E$275,3,0) -> 03-2026/TS-AVP/ĐĐH | O7: 46028 | P7: 00000024 | Q7: 1200 | R7: 17900.8 | S7: 21480960 | T7: 1718477 | U7: =S7+T7 -> 23199437
A8: 46029 | B8: 00000010 | C8: TP-LG00003-BT | D8: Lưỡi gà trắng 95 - LGT95/TS-BT 95mm x 800m x 210gsm, 15.96kg/cuộn | E8: CÔNG TY TNHH MỘT THÀNH VIÊN THUỐC LÁ BẾN TRE | F8: Cuộn | G8: 104 | H8: 502740 | I8: 52284960 | J8: 4182797 | K8: 56467757 | L8: 13-12/2025Hàng SXTP-LG00003-BT | M8: =VLOOKUP(L8,'Đơn đặt'!$C$3:$E$275,2,0) -> 13-12/2025 | N8: =VLOOKUP(L8,'Đơn đặt'!$C$3:$E$275,3,0) -> Hàng SX | O8: Hàng SX | Q8: =G8 -> 104 | S8: =ROUND(Q8*R8,0) -> 0 | T8: =ROUND(S8*0.08,0) -> 0 | U8: =S8+T8 -> 0
A9: 46029 | B9: 00000011 | C9: TP-LG00003-BT | D9: Lưỡi gà trắng 95 - LGT95/TS-BT 95mm x 800m x 210gsm, 15.96kg/cuộn | E9: CÔNG TY TNHH MỘT THÀNH VIÊN THUỐC LÁ BẾN TRE | F9: Cuộn | G9: 156 | H9: 502740 | I9: 78427440 | J9: 6274195 | K9: 84701635 | L9: 13-12/2025Hàng SXTP-LG00003-BT | M9: =VLOOKUP(L9,'Đơn đặt'!$C$3:$E$275,2,0) -> 13-12/2025 | N9: =VLOOKUP(L9,'Đơn đặt'!$C$3:$E$275,3,0) -> Hàng SX | O9: Hàng SX | Q9: =G9 -> 156 | S9: =ROUND(Q9*R9,0) -> 0 | T9: =ROUND(S9*0.08,0) -> 0 | U9: =S9+T9 -> 0
A10: 46029 | B10: 00000016 | C10: HH-CT00131 | D10: Thùng carton SAIGON Silver Capsule DS BC | E10: CÔNG TY TNHH MỘT THÀNH VIÊN THUỐC LÁ SÀI GÒN | F10: Cái | G10: 1560 | H10: 18291 | I10: 28533960 | J10: 2282717 | K10: 30816677 | L10: 11-10-TS02-2026/TS-AVP/ĐĐHHH-CT00131 | M10: =VLOOKUP(L10,'Đơn đặt'!$C$3:$E$275,2,0) -> 11-10-TS | N10: =VLOOKUP(L10,'Đơn đặt'!$C$3:$E$275,3,0) -> 02-2026/TS-AVP/ĐĐH | O10: 46029 | P10: 00000034 | Q10: 1560 | R10: 16258.2 | S10: 25362792 | T10: 2029023 | U10: =S10+T10 -> 27391815
A11: 46029 | B11: 00000017 | C11: TP-LG00008-SG | D11: Giấy lưỡi gà trắng - LGT90-TS 90mm x 800m x 250gsm (PO 11/08/TSC-LT - 156 cuộn) | E11: CÔNG TY TNHH MỘT THÀNH VIÊN THUỐC LÁ SÀI GÒN | F11: kg | G11: 2808 | H11: 28000 | I11: 78624000 | J11: 6289920 | K11: 84913920 | L11: 11/08/TSC-LTHàng SXTP-LG00008-SG | M11: =VLOOKUP(L11,'Đơn đặt'!$C$3:$E$275,2,0) -> 11/08/TSC-LT | N11: =VLOOKUP(L11,'Đơn đặt'!$C$3:$E$275,3,0) -> Hàng SX | O11: Hàng SX | Q11: =G11 -> 2808 | S11: =ROUND(Q11*R11,0) -> 0 | T11: =ROUND(S11*0.08,0) -> 0 | U11: =S11+T11 -> 0
A12: 46030 | B12: 00000019 | C12: HH-CT00131 | D12: Thùng carton SAIGON Silver Capsule DS BC | E12: CÔNG TY TNHH MỘT THÀNH VIÊN THUỐC LÁ SÀI GÒN | F12: Cái | G12: 440 | H12: 18291 | I12: 8048040 | J12: 643843 | K12: 8691883 | L12: 11-10-TS02-2026/TS-AVP/ĐĐHHH-CT00131 | M12: =VLOOKUP(L12,'Đơn đặt'!$C$3:$E$275,2,0) -> 11-10-TS | N12: =VLOOKUP(L12,'Đơn đặt'!$C$3:$E$275,3,0) -> 02-2026/TS-AVP/ĐĐH | O12: 46030 | P12: 00000036 | Q12: 440 | R12: 16258.2 | S12: 7153608 | T12: 572289 | U12: =S12+T12 -> 7725897
A13: 46030 | B13: 00000019 | C13: HH-CT00025 | D13: Thùng carton ERA Premium - OD | E13: CÔNG TY TNHH MỘT THÀNH VIÊN THUỐC LÁ SÀI GÒN | F13: Cái | G13: 2000 | H13: 19310 | I13: 38620000 | J13: 3089600 | K13: 41709600 | L13: 11-04-TS01-2026/TS-AVP/ĐĐHHH-CT00025 | M13: =VLOOKUP(L13,'Đơn đặt'!$C$3:$E$275,2,0) -> 11-04-TS | N13: =VLOOKUP(L13,'Đơn đặt'!$C$3:$E$275,3,0) -> 01-2026/TS-AVP/ĐĐH | O13: 46030 | P13: 00000036 | Q13: 2000 | R13: 17438 | S13: 34876000 | T13: 2790080 | U13: =S13+T13 -> 37666080
A14: 46030 | B14: 00000020 | C14: HH-CT00007 | D14: Thùng carton SAIGON Silver DS-TĐ | E14: CÔNG TY TNHH MỘT THÀNH VIÊN THUỐC LÁ SÀI GÒN | F14: Cái | G14: 3000 | H14: 18291 | I14: 54873000 | J14: 4389840 | K14: 59262840 | L14: 11-10-TS137-2025/TS-AVP/ĐĐHHH-CT00007 | M14: =VLOOKUP(L14,'Đơn đặt'!$C$3:$E$275,2,0) -> 11-10-TS | N14: =VLOOKUP(L14,'Đơn đặt'!$C$3:$E$275,3,0) -> 137-2025/TS-AVP/ĐĐH | O14: 46030 | P14: 00000037 | Q14: 3000 | R14: 14018.2 | S14: 42054600 | T14: 3364368 | U14: =S14+T14 -> 45418968
A15: 46032 | B15: 00000021 | C15: HH-CT00131 | D15: Thùng carton SAIGON Silver Capsule DS BC | E15: CÔNG TY TNHH MỘT THÀNH VIÊN THUỐC LÁ SÀI GÒN | F15: Cái | G15: 4000 | H15: 18291 | I15: 73164000 | J15: 5853120 | K15: 79017120 | L15: 11-10-TS02-2026/TS-AVP/ĐĐHHH-CT00131 | M15: =VLOOKUP(L15,'Đơn đặt'!$C$3:$E$275,2,0) -> 11-10-TS | N15: =VLOOKUP(L15,'Đơn đặt'!$C$3:$E$275,3,0) -> 02-2026/TS-AVP/ĐĐH | O15: 46031 | P15: 00000044 | Q15: 4000 | R15: 16258.2 | S15: 65032800 | T15: 5202624 | U15: =S15+T15 -> 70235424
A16: 46032 | B16: 00000022 | C16: HH-CT00007 | D16: Thùng carton SAIGON Silver DS-TĐ | E16: CÔNG TY TNHH MỘT THÀNH VIÊN THUỐC LÁ SÀI GÒN | F16: Cái | G16: 3000 | H16: 18291 | I16: 54873000 | J16: 4389840 | K16: 59262840 | L16: 11-10-TS137-2025/TS-AVP/ĐĐHHH-CT00007 | M16: =VLOOKUP(L16,'Đơn đặt'!$C$3:$E$275,2,0) -> 11-10-TS | N16: =VLOOKUP(L16,'Đơn đặt'!$C$3:$E$275,3,0) -> 137-2025/TS-AVP/ĐĐH | O16: 46031 | P16: 00000043 | Q16: 3000 | R16: 14018.2 | S16: 42054600 | T16: 3364368 | U16: =S16+T16 -> 45418968
A17: 46032 | B17: 00000023 | C17: TP-LG00003-BT | D17: Lưỡi gà trắng 95 - LGT95/TS-BT 95mm x 800m x 210gsm, 15.96kg/cuộn | E17: CÔNG TY TNHH MỘT THÀNH VIÊN THUỐC LÁ BẾN TRE | F17: Cuộn | G17: 260 | H17: 502740 | I17: 130712400 | J17: 10456992 | K17: 141169392 | L17: 02-01/2026Hàng SXTP-LG00003-BT | M17: =VLOOKUP(L17,'Đơn đặt'!$C$3:$E$275,2,0) -> 02-01/2026 | N17: =VLOOKUP(L17,'Đơn đặt'!$C$3:$E$275,3,0) -> Hàng SX | O17: Hàng SX | Q17: =G17 -> 260 | S17: =ROUND(Q17*R17,0) -> 0 | T17: =ROUND(S17*0.08,0) -> 0 | U17: =S17+T17 -> 0
A18: 46036 | B18: 00000037 | C18: TP-PE00006 | D18: Túi PE 85 x 70 cm | E18: CÔNG TY TNHH MỘT THÀNH VIÊN THUỐC LÁ SÀI GÒN | F18: kg | G18: 1000 | H18: 38000 | I18: 38000000 | J18: 3040000 | K18: 41040000 | L18: 12-38/TS-LP150-2025/TS-AVP/ĐĐHTP-PE00006 | M18: =VLOOKUP(L18,'Đơn đặt'!$C$3:$E$275,2,0) -> 12-38/TS-LP | N18: =VLOOKUP(L18,'Đơn đặt'!$C$3:$E$275,3,0) -> 150-2025/TS-AVP/ĐĐH | O18: 46032 | P18: 00000046 | Q18: 1000 | R18: 34800 | S18: =ROUND(Q18*R18,0) -> 34800000 | T18: =S18*0.08 -> 2784000 | U18: =S18+T18 -> 37584000
A19: 46036 | B19: 00000037 | C19: TP-PE00004 | D19: Túi PE 52 x 100 cm | E19: CÔNG TY TNHH MỘT THÀNH VIÊN THUỐC LÁ SÀI GÒN | F19: kg | G19: 4000 | H19: 38000 | I19: 152000000 | J19: 12160000 | K19: 164160000 | L19: 12-38/TS-LP150-2025/TS-AVP/ĐĐHTP-PE00004 | M19: =VLOOKUP(L19,'Đơn đặt'!$C$3:$E$275,2,0) -> 12-38/TS-LP | N19: =VLOOKUP(L19,'Đơn đặt'!$C$3:$E$275,3,0) -> 150-2025/TS-AVP/ĐĐH | O19: 46032 | P19: 00000046 | Q19: 4000 | R19: 34800 | S19: =ROUND(Q19*R19,0) -> 139200000 | T19: =S19*0.08 -> 11136000 | U19: =S19+T19 -> 150336000
A20: 46036 | B20: 00000038 | C20: HH-CT00131 | D20: Thùng carton SAIGON Silver Capsule DS BC | E20: CÔNG TY TNHH MỘT THÀNH VIÊN THUỐC LÁ SÀI GÒN | F20: Cái | G20: 2000 | H20: 18291 | I20: 36582000 | J20: 2926560 | K20: 39508560 | L20: 11-10-TS02-2026/TS-AVP/ĐĐHHH-CT00131 | M20: =VLOOKUP(L20,'Đơn đặt'!$C$3:$E$275,2,0) -> 11-10-TS | N20: =VLOOKUP(L20,'Đơn đặt'!$C$3:$E$275,3,0) -> 02-2026/TS-AVP/ĐĐH | O20: 46034 | P20: 00000052 | Q20: 2000 | R20: 16258.2 | S20: 32516400 | T20: 2601312 | U20: =S20+T20 -> 35117712
A21: 46036 | B21: 00000038 | C21: HH-CT00025 | D21: Thùng carton ERA Premium - OD | E21: CÔNG TY TNHH MỘT THÀNH VIÊN THUỐC LÁ SÀI GÒN | F21: Cái | G21: 2000 | H21: 19310 | I21: 38620000 | J21: 3089600 | K21: 41709600 | L21: 11-04-TS01-2026/TS-AVP/ĐĐHHH-CT00025 | M21: =VLOOKUP(L21,'Đơn đặt'!$C$3:$E$275,2,0) -> 11-04-TS | N21: =VLOOKUP(L21,'Đơn đặt'!$C$3:$E$275,3,0) -> 01-2026/TS-AVP/ĐĐH | O21: 46034 | P21: 00000052 | Q21: 2000 | R21: 17438 | S21: 34876000 | T21: 2790080 | U21: =S21+T21 -> 37666080
A22: 46036 | B22: 00000039 | C22: HH-CT00007 | D22: Thùng carton SAIGON Silver DS-TĐ | E22: CÔNG TY TNHH MỘT THÀNH VIÊN THUỐC LÁ SÀI GÒN | F22: Cái | G22: 5000 | H22: 18291 | I22: 91455000 | J22: 7316400 | K22: 98771400 | L22: 11-10-TS137-2025/TS-AVP/ĐĐHHH-CT00007 | M22: =VLOOKUP(L22,'Đơn đặt'!$C$3:$E$275,2,0) -> 11-10-TS | N22: =VLOOKUP(L22,'Đơn đặt'!$C$3:$E$275,3,0) -> 137-2025/TS-AVP/ĐĐH | O22: 46032 | P22: 00000049 | Q22: 5000 | R22: 14018.2 | S22: 70091000 | T22: 5607280 | U22: =S22+T22 -> 75698280
A23: 46036 | B23: 00000039 | C23: HH-CT00064 | D23: Thùng carton GREENHILL 100SP MENTHOL | E23: CÔNG TY TNHH MỘT THÀNH VIÊN THUỐC LÁ SÀI GÒN | F23: Cái | G23: 1000 | H23: 21777 | I23: 21777000 | J23: 1742160 | K23: 23519160 | L23: 12-09-TS149-2025/TS-AVP/ĐĐHHH-CT00064 | M23: =VLOOKUP(L23,'Đơn đặt'!$C$3:$E$275,2,0) -> 12-09-TS | N23: =VLOOKUP(L23,'Đơn đặt'!$C$3:$E$275,3,0) -> 149-2025/TS-AVP/ĐĐH | O23: 46032 | P23: 00000049 | Q23: 1000 | R23: 19059.4 | S23: 19059400 | T23: 1524752 | U23: =S23+T23 -> 20584152
A24: 46036 | B24: 00000040 | C24: HH-CT00131 | D24: Thùng carton SAIGON Silver Capsule DS BC | E24: CÔNG TY TNHH MỘT THÀNH VIÊN THUỐC LÁ SÀI GÒN | F24: Cái | G24: 2000 | H24: 18291 | I24: 36582000 | J24: 2926560 | K24: 39508560 | L24: 11-10-TS02-2026/TS-AVP/ĐĐHHH-CT00131 | M24: =VLOOKUP(L24,'Đơn đặt'!$C$3:$E$275,2,0) -> 11-10-TS | N24: =VLOOKUP(L24,'Đơn đặt'!$C$3:$E$275,3,0) -> 02-2026/TS-AVP/ĐĐH | O24: 46034 | P24: 00000055 | Q24: 2000 | R24: 16258.2 | S24: 32516400 | T24: 2601312 | U24: =S24+T24 -> 35117712
A25: 46036 | B25: 00000040 | C25: HH-CT00025 | D25: Thùng carton ERA Premium - OD | E25: CÔNG TY TNHH MỘT THÀNH VIÊN THUỐC LÁ SÀI GÒN | F25: Cái | G25: 2000 | H25: 19310 | I25: 38620000 | J25: 3089600 | K25: 41709600 | L25: 11-04-TS01-2026/TS-AVP/ĐĐHHH-CT00025 | M25: =VLOOKUP(L25,'Đơn đặt'!$C$3:$E$275,2,0) -> 11-04-TS | N25: =VLOOKUP(L25,'Đơn đặt'!$C$3:$E$275,3,0) -> 01-2026/TS-AVP/ĐĐH | O25: 46034 | P25: 00000055 | Q25: 2000 | R25: 17438 | S25: 34876000 | T25: 2790080 | U25: =S25+T25 -> 37666080
A26: 46036 | B26: 00000041 | C26: HH-CT00007 | D26: Thùng carton SAIGON Silver DS-TĐ | E26: CÔNG TY TNHH MỘT THÀNH VIÊN THUỐC LÁ SÀI GÒN | F26: Cái | G26: 3000 | H26: 18291 | I26: 54873000 | J26: 4389840 | K26: 59262840 | L26: 11-10-TS137-2025/TS-AVP/ĐĐHHH-CT00007 | M26: =VLOOKUP(L26,'Đơn đặt'!$C$3:$E$275,2,0) -> 11-10-TS | N26: =VLOOKUP(L26,'Đơn đặt'!$C$3:$E$275,3,0) -> 137-2025/TS-AVP/ĐĐH | O26: 46034 | P26: 00000056 | Q26: 3000 | R26: 14018.2 | S26: 42054600 | T26: 3364368 | U26: =S26+T26 -> 45418968
A27: 46036 | B27: 00000042 | C27: HH-CT00007 | D27: Thùng carton SAIGON Silver DS-TĐ | E27: CÔNG TY TNHH MỘT THÀNH VIÊN THUỐC LÁ SÀI GÒN | F27: Cái | G27: 3000 | H27: 18291 | I27: 54873000 | J27: 4389840 | K27: 59262840 | L27: 11-10-TS137-2025/TS-AVP/ĐĐHHH-CT00007 | M27: =VLOOKUP(L27,'Đơn đặt'!$C$3:$E$275,2,0) -> 11-10-TS | N27: =VLOOKUP(L27,'Đơn đặt'!$C$3:$E$275,3,0) -> 137-2025/TS-AVP/ĐĐH | O27: 46035 | P27: 00000067 | Q27: 3000 | R27: 14018.2 | S27: 42054600 | T27: 3364368 | U27: =S27+T27 -> 45418968
A28: 46036 | B28: 00000042 | C28: HH-CT00064 | D28: Thùng carton GREENHILL 100SP MENTHOL | E28: CÔNG TY TNHH MỘT THÀNH VIÊN THUỐC LÁ SÀI GÒN | F28: Cái | G28: 1000 | H28: 21777 | I28: 21777000 | J28: 1742160 | K28: 23519160 | L28: 12-09-TS149-2025/TS-AVP/ĐĐHHH-CT00064 | M28: =VLOOKUP(L28,'Đơn đặt'!$C$3:$E$275,2,0) -> 12-09-TS | N28: =VLOOKUP(L28,'Đơn đặt'!$C$3:$E$275,3,0) -> 149-2025/TS-AVP/ĐĐH | O28: 46035 | P28: 00000067 | Q28: 1000 | R28: 19059.4 | S28: 19059400 | T28: 1524752 | U28: =S28+T28 -> 20584152
A29: 46038 | B29: 00000057 | C29: HH-CT00036 | D29: Thùng carton COTAB BC-TĐ | E29: CÔNG TY TNHH MỘT THÀNH VIÊN THUỐC LÁ SÀI GÒN | F29: Cái | G29: 1400 | H29: 19404 | I29: 27165600 | J29: 2173248 | K29: 29338848 | L29: 11-10-TS02-2026/TS-AVP/ĐĐHHH-CT00036 | M29: =VLOOKUP(L29,'Đơn đặt'!$C$3:$E$275,2,0) -> 11-10-TS | N29: =VLOOKUP(L29,'Đơn đặt'!$C$3:$E$275,3,0) -> 02-2026/TS-AVP/ĐĐH | O29: 46036 | P29: 00000076 | Q29: 1400 | R29: 17776.8 | S29: 24887520 | T29: 1991002 | U29: =S29+T29 -> 26878522
A30: 46038 | B30: 00000058 | C30: TP-PE00001 | D30: Túi PE 54 x 92 cm | E30: CÔNG TY TNHH MỘT THÀNH VIÊN THUỐC LÁ SÀI GÒN | F30: kg | G30: 5000 | H30: 38000 | I30: 190000000 | J30: 15200000 | K30: 205200000 | L30: 12-38/TS-LP150-2025/TS-AVP/ĐĐHTP-PE00001 | M30: =VLOOKUP(L30,'Đơn đặt'!$C$3:$E$275,2,0) -> 12-38/TS-LP | N30: =VLOOKUP(L30,'Đơn đặt'!$C$3:$E$275,3,0) -> 150-2025/TS-AVP/ĐĐH | O30: 46036 | P30: 00000077 | Q30: 5000 | R30: 34800 | S30: 174000000 | T30: 13920000 | U30: =S30+T30 -> 187920000
A31: 46038 | B31: 00000059 | C31: HH-CT00007 | D31: Thùng carton SAIGON Silver DS-TĐ | E31: CÔNG TY TNHH MỘT THÀNH VIÊN THUỐC LÁ SÀI GÒN | F31: Cái | G31: 2000 | H31: 18291 | I31: 36582000 | J31: 2926560 | K31: 39508560 | L31: 11-10-TS137-2025/TS-AVP/ĐĐHHH-CT00007 | M31: =VLOOKUP(L31,'Đơn đặt'!$C$3:$E$275,2,0) -> 11-10-TS | N31: =VLOOKUP(L31,'Đơn đặt'!$C$3:$E$275,3,0) -> 137-2025/TS-AVP/ĐĐH | O31: 46036 | P31: 00000075 | Q31: 2000 | R31: 14018.2 | S31: 28036400 | T31: 2242912 | U31: =S31+T31 -> 30279312
... A36: 46038 | B36: 00000062 | C36: HH-CT00064 | D36: Thùng carton GREENHILL 100SP MENTHOL | E36: CÔNG TY TNHH MỘT THÀNH VIÊN THUỐC LÁ SÀI GÒN | F36: Cái | G36: 1000 | H36: 21777 | I36: 21777000 | J36: 1742160 | K36: 23519160 | L36: 12-09-TS149-2025/TS-AVP/ĐĐHHH-CT00064 | M36: =VLOOKUP(L36,'Đơn đặt'!$C$3:$E$275,2,0) -> 12-09-TS | N36: =VLOOKUP(L36,'Đơn đặt'!$C$3:$E$275,3,0) -> 149-2025/TS-AVP/ĐĐH | O36: 46037 | P36: 00000087 | Q36: 1000 | R36: 19059.4 | S36: 19059400 | T36: 1524752 | U36: =S36+T36 -> 20584152
A37: 46038 | B37: 00000073 | C37: HH-CT00133 | D37: Thùng carton GREENHILL 100SP FF | E37: CÔNG TY TNHH THƯƠNG MẠI VÀ ĐẦU TƯ QUỐC ĐẠI | F37: Cái | G37: 800 | H37: 4629.63 | I37: 3703704 | J37: 296296 | K37: 4000000 | L37: Hàng thanh lý - ko DDH | M37: Hàng thanh lý - ko DDH | N37: Hàng thanh lý - ko DDH | O37: 2025 | Q37: 800 | S37: =ROUND(Q37*R37,0) -> 0 | T37: =ROUND(S37*0.08,0) -> 0 | U37: =S37+T37 -> 0
A38: 46038 | B38: 00000074 | C38: TP-PE00001 | D38: Túi PE 54 x 92 cm | E38: CÔNG TY TNHH MỘT THÀNH VIÊN THUỐC LÁ SÀI GÒN | F38: kg | G38: 5000 | H38: 38000 | I38: 190000000 | J38: 15200000 | K38: 205200000 | L38: 12-38/TS-LP150-2025/TS-AVP/ĐĐHTP-PE00001 | M38: =VLOOKUP(L38,'Đơn đặt'!$C$3:$E$275,2,0) -> 12-38/TS-LP | N38: =VLOOKUP(L38,'Đơn đặt'!$C$3:$E$275,3,0) -> 150-2025/TS-AVP/ĐĐH | O38: 46038 | P38: 00000109 | Q38: 5000 | R38: 34800 | S38: 174000000 | T38: 13920000 | U38: =S38+T38 -> 187920000
A39: 46038 | B39: 00000075 | C39: HH-CT00007 | D39: Thùng carton SAIGON Silver DS-TĐ | E39: CÔNG TY TNHH MỘT THÀNH VIÊN THUỐC LÁ SÀI GÒN | F39: Cái | G39: 2000 | H39: 18291 | I39: 36582000 | J39: 2926560 | K39: 39508560 | L39: 11-10-TS137-2025/TS-AVP/ĐĐHHH-CT00007 | M39: =VLOOKUP(L39,'Đơn đặt'!$C$3:$E$275,2,0) -> 11-10-TS | N39: =VLOOKUP(L39,'Đơn đặt'!$C$3:$E$275,3,0) -> 137-2025/TS-AVP/ĐĐH | O39: 46038 | P39: 00000108 | Q39: 2000 | R39: 14018.2 | S39: 28036400 | T39: 2242912 | U39: =S39+T39 -> 30279312
A40: 46038 | B40: 00000076 | C40: HH-CT00025 | D40: Thùng carton ERA Premium - OD | E40: CÔNG TY TNHH MỘT THÀNH VIÊN THUỐC LÁ SÀI GÒN | F40: Cái | G40: 995 | H40: 19310 | I40: 19213450 | J40: 1537076 | K40: 20750526 | L40: 11-04-TS01-2026/TS-AVP/ĐĐHHH-CT00025 | M40: =VLOOKUP(L40,'Đơn đặt'!$C$3:$E$275,2,0) -> 11-04-TS | N40: =VLOOKUP(L40,'Đơn đặt'!$C$3:$E$275,3,0) -> 01-2026/TS-AVP/ĐĐH | O40: 46038 | P40: 00000111 | Q40: 995 | R40: 17438 | S40: =ROUND(Q40*R40,0) -> 17350810 | T40: =ROUND(S40*0.08,0) -> 1388065 | U40: =S40+T40 -> 18738875
A41: 46038 | B41: 00000076 | C41: HH-CT00006 | D41: Thùng carton HÒA BÌNH BM-TĐ | E41: CÔNG TY TNHH MỘT THÀNH VIÊN THUỐC LÁ SÀI GÒN | F41: Cái | G41: 1000 | H41: 14900 | I41: 14900000 | J41: 1192000 | K41: 16092000 | L41: 12-01-TS03-2026/TS-AVP/ĐĐHHH-CT00006 | M41: =VLOOKUP(L41,'Đơn đặt'!$C$3:$E$275,2,0) -> 12-01-TS | N41: =VLOOKUP(L41,'Đơn đặt'!$C$3:$E$275,3,0) -> 03-2026/TS-AVP/ĐĐH | O41: 46038 | P41: 00000111 | Q41: 1000 | R41: 14140 | S41: 14140000 | T41: 1131200 | U41: =S41+T41 -> 15271200
A42: 46038 | B42: 00000076 | C42: HH-CT00095 | D42: Thùng carton GOLD SEAL 20 Ment (C) | E42: CÔNG TY TNHH MỘT THÀNH VIÊN THUỐC LÁ SÀI GÒN | F42: Cái | G42: 495 | H42: 19320 | I42: 9563400 | J42: 765072 | K42: 10328472 | L42: 01-03-TS06-2026/TS-AVP/ĐĐHHH-CT00095 | M42: =VLOOKUP(L42,'Đơn đặt'!$C$3:$E$275,2,0) -> 01-03-TS | N42: =VLOOKUP(L42,'Đơn đặt'!$C$3:$E$275,3,0) -> 06-2026/TS-AVP/ĐĐH | O42: 46038 | P42: 00000111 | Q42: 495 | R42: 17928 | S42: 8874360 | T42: 709949 | U42: =S42+T42 -> 9584309
A43: 46038 | B43: 00000077 | C43: HH-CT00036 | D43: Thùng carton COTAB BC-TĐ | E43: CÔNG TY TNHH MỘT THÀNH VIÊN THUỐC LÁ SÀI GÒN | F43: Cái | G43: 1500 | H43: 19404 | I43: 29106000 | J43: 2328480 | K43: 31434480 | L43: 11-10-TS02-2026/TS-AVP/ĐĐHHH-CT00036 | M43: =VLOOKUP(L43,'Đơn đặt'!$C$3:$E$275,2,0) -> 11-10-TS | N43: =VLOOKUP(L43,'Đơn đặt'!$C$3:$E$275,3,0) -> 02-2026/TS-AVP/ĐĐH | O43: 46038 | P43: 00000110 | Q43: 1500 | R43: 17776.8 | S43: =ROUND(Q43*R43,0) -> 26665200 | T43: =ROUND(S43*0.08,0) -> 2133216 | U43: =S43+T43 -> 28798416
A44: 46038 | B44: 00000077 | C44: HH-CT00131 | D44: Thùng carton SAIGON Silver Capsule DS BC | E44: CÔNG TY TNHH MỘT THÀNH VIÊN THUỐC LÁ SÀI GÒN | F44: Cái | G44: 2000 | H44: 18291 | I44: 36582000 | J44: 2926560 | K44: 39508560 | L44: 11-10-TS02-2026/TS-AVP/ĐĐHHH-CT00131 | M44: =VLOOKUP(L44,'Đơn đặt'!$C$3:$E$275,2,0) -> 11-10-TS | N44: =VLOOKUP(L44,'Đơn đặt'!$C$3:$E$275,3,0) -> 02-2026/TS-AVP/ĐĐH | O44: 46038 | P44: 00000110 | Q44: 2000 | R44: 16258.2 | S44: 32516400 | T44: 2601312 | U44: =S44+T44 -> 35117712
A45: 46042 | B45: 00000092 | C45: HH-CT00131 | D45: Thùng carton SAIGON Silver Capsule DS BC | E45: CÔNG TY TNHH MỘT THÀNH VIÊN THUỐC LÁ SÀI GÒN | F45: Cái | G45: 800 | H45: 18291 | I45: 14632800 | J45: 1170624 | K45: 15803424 | L45: 11-10-TS02-2026/TS-AVP/ĐĐHHH-CT00131 | M45: =VLOOKUP(L45,'Đơn đặt'!$C$3:$E$275,2,0) -> 11-10-TS | N45: =VLOOKUP(L45,'Đơn đặt'!$C$3:$E$275,3,0) -> 02-2026/TS-AVP/ĐĐH | O45: 46041 | P45: 00000127 | Q45: 800 | R45: 16258.2 | S45: 13006560 | T45: 1040525 | U45: =S45+T45 -> 14047085
...

Sheet Đơn đặt
K1: =H14+I14+H15+I15+H16+I16+H17+I17-J14-J15-J16-J17 -> 1458.4
H2: =SUBTOTAL(9,H3:H364) -> 3025750 | I2: =SUBTOTAL(9,I3:I364) -> 0 | J2: =SUBTOTAL(9,J3:J364) -> 0 | K2: =SUBTOTAL(9,K3:K364) -> 1305750
A3: Khách hàng | B3: Ngày đặt | D3: Đơn đặt hàng khách hàng | E3: Đơn đặt hàng AVP | F3: Mã hàng | G3: Tên hàng | H3: Số lượng PO | I3: +-10% theo PO | J3: SL giao hoàn thành | K3: CL | L3: % CHÊNH LỆCH | M3: Mua AVP | N3: CL
A4: Quốc Đại | C4: Hàng thanh lý - ko DDH | F4: HH-CT00133 | G4: Thùng carton GREENHILL 100SP FF
A5: Bắc Sơn | B5: 46084 | C5: =D5&E5&F5 -> 15126/YFY/01HH-CT00149 | D5: 151 | E5: 26/YFY/01 | F5: HH-CT00149 | G5: Thùng V5 (Red-XK) C5-15 | H5: 1000 | J5: =SUMIFS('SỔ CHI TIẾT BÁN HÀNG'!$G$5:$G$2062,'SỔ CHI TIẾT BÁN HÀNG'!$C$5:$C$2062,'Đơn đặt'!F5,'SỔ CHI TIẾT BÁN HÀNG'!$L$5:$L$2062,'Đơn đặt'!C5) -> 1000 | K5: =H5+I5-J5 -> 0 | M5: =IF(E5="Hàng SX",0,SUMIFS('SỔ CHI TIẾT BÁN HÀNG'!$Q$5:$Q$2863,'SỔ CHI TIẾT BÁN HÀNG'!$C$5:$C$2863,'Đơn đặt'!F5,'SỔ CHI TIẾT BÁN HÀNG'!$N$5:$N$2863,'Đơn đặt'!E5)) -> 1000 | N5: =IF(E5="Hàng SX",0,H5-M5) -> 0 | P5: ok
A6: Bắc Sơn | B6: 46084 | C6: =D6&E6&F6 -> 151a26/TB/01HH-NT00038 | D6: 151a | E6: 26/TB/01 | F6: HH-NT00038 | G6: Nhãn BlueSky (Red-XK) | H6: 27000 | J6: =SUMIFS('SỔ CHI TIẾT BÁN HÀNG'!$G$5:$G$2062,'SỔ CHI TIẾT BÁN HÀNG'!$C$5:$C$2062,'Đơn đặt'!F6,'SỔ CHI TIẾT BÁN HÀNG'!$L$5:$L$2062,'Đơn đặt'!C6) -> 27000 | K6: =H6+I6-J6 -> 0 | M6: =IF(E6="Hàng SX",0,SUMIFS('SỔ CHI TIẾT BÁN HÀNG'!$Q$5:$Q$2863,'SỔ CHI TIẾT BÁN HÀNG'!$C$5:$C$2863,'Đơn đặt'!F6,'SỔ CHI TIẾT BÁN HÀNG'!$N$5:$N$2863,'Đơn đặt'!E6)) -> 27000 | N6: =IF(E6="Hàng SX",0,H6-M6) -> 0 | P6: ok
A7: Bắc Sơn | B7: 46084 | C7: =D7&E7&F7 -> 151a26/TB/01HH-NT00039 | D7: 151a | E7: 26/TB/01 | F7: HH-NT00039 | G7: Nhãn V5 (Red-XK) | H7: 541000 | J7: =SUMIFS('SỔ CHI TIẾT BÁN HÀNG'!$G$5:$G$2062,'SỔ CHI TIẾT BÁN HÀNG'!$C$5:$C$2062,'Đơn đặt'!F7,'SỔ CHI TIẾT BÁN HÀNG'!$L$5:$L$2062,'Đơn đặt'!C7) -> 541000 | K7: =H7+I7-J7 -> 0 | M7: =IF(E7="Hàng SX",0,SUMIFS('SỔ CHI TIẾT BÁN HÀNG'!$Q$5:$Q$2863,'SỔ CHI TIẾT BÁN HÀNG'!$C$5:$C$2863,'Đơn đặt'!F7,'SỔ CHI TIẾT BÁN HÀNG'!$N$5:$N$2863,'Đơn đặt'!E7)) -> 541000 | N7: =IF(E7="Hàng SX",0,H7-M7) -> 0 | P7: ok
A8: Bắc Sơn | B8: 46120 | C8: =D8&E8&F8 -> 23226/YFY/02HH-CT00149 | D8: 232 | E8: 26/YFY/02 | F8: HH-CT00149 | G8: Thùng V5 (Red-XK) C5-15 | H8: 700 | J8: =SUMIFS('SỔ CHI TIẾT BÁN HÀNG'!$G$5:$G$2062,'SỔ CHI TIẾT BÁN HÀNG'!$C$5:$C$2062,'Đơn đặt'!F8,'SỔ CHI TIẾT BÁN HÀNG'!$L$5:$L$2062,'Đơn đặt'!C8) -> 700 | K8: =H8+I8-J8 -> 0 | M8: =IF(E8="Hàng SX",0,SUMIFS('SỔ CHI TIẾT BÁN HÀNG'!$Q$5:$Q$2863,'SỔ CHI TIẾT BÁN HÀNG'!$C$5:$C$2863,'Đơn đặt'!F8,'SỔ CHI TIẾT BÁN HÀNG'!$N$5:$N$2863,'Đơn đặt'!E8)) -> 700 | N8: =IF(E8="Hàng SX",0,H8-M8) -> 0 | P8: ok
A9: Bắc Sơn | B9: 46120 | C9: =D9&E9&F9 -> 23226/YFY/02HH-CT00150 | D9: 232 | E9: 26/YFY/02 | F9: HH-CT00150 | G9: Thùng Laguna (Red-XK) C5-16 | H9: 350 | J9: =SUMIFS('SỔ CHI TIẾT BÁN HÀNG'!$G$5:$G$2062,'SỔ CHI TIẾT BÁN HÀNG'!$C$5:$C$2062,'Đơn đặt'!F9,'SỔ CHI TIẾT BÁN HÀNG'!$L$5:$L$2062,'Đơn đặt'!C9) -> 350 | K9: =H9+I9-J9 -> 0 | M9: =IF(E9="Hàng SX",0,SUMIFS('SỔ CHI TIẾT BÁN HÀNG'!$Q$5:$Q$2863,'SỔ CHI TIẾT BÁN HÀNG'!$C$5:$C$2863,'Đơn đặt'!F9,'SỔ CHI TIẾT BÁN HÀNG'!$N$5:$N$2863,'Đơn đặt'!E9)) -> 350 | N9: =IF(E9="Hàng SX",0,H9-M9) -> 0 | P9: ok
A10: Bắc Sơn | B10: 46120 | C10: =D10&E10&F10 -> 232a26/TB/02HH-NT00039 | D10: 232a | E10: 26/TB/02 | F10: HH-NT00039 | G10: Nhãn V5 (Red-XK) | H10: 351000 | J10: =SUMIFS('SỔ CHI TIẾT BÁN HÀNG'!$G$5:$G$2062,'SỔ CHI TIẾT BÁN HÀNG'!$C$5:$C$2062,'Đơn đặt'!F10,'SỔ CHI TIẾT BÁN HÀNG'!$L$5:$L$2062,'Đơn đặt'!C10) -> 351000 | K10: =H10+I10-J10 -> 0 | M10: =IF(E10="Hàng SX",0,SUMIFS('SỔ CHI TIẾT BÁN HÀNG'!$Q$5:$Q$2863,'SỔ CHI TIẾT BÁN HÀNG'!$C$5:$C$2863,'Đơn đặt'!F10,'SỔ CHI TIẾT BÁN HÀNG'!$N$5:$N$2863,'Đơn đặt'!E10)) -> 351000 | N10: =IF(E10="Hàng SX",0,H10-M10) -> 0 | P10: ok
A11: Bắc Sơn | B11: 46120 | C11: =D11&E11&F11 -> 232a26/TB/02HH-NT00040 | D11: 232a | E11: 26/TB/02 | F11: HH-NT00040 | G11: Nhãn Laguna (Red-XK) | H11: 183000 | J11: =SUMIFS('SỔ CHI TIẾT BÁN HÀNG'!$G$5:$G$2062,'SỔ CHI TIẾT BÁN HÀNG'!$C$5:$C$2062,'Đơn đặt'!F11,'SỔ CHI TIẾT BÁN HÀNG'!$L$5:$L$2062,'Đơn đặt'!C11) -> 183000 | K11: =H11+I11-J11 -> 0 | M11: =IF(E11="Hàng SX",0,SUMIFS('SỔ CHI TIẾT BÁN HÀNG'!$Q$5:$Q$2863,'SỔ CHI TIẾT BÁN HÀNG'!$C$5:$C$2863,'Đơn đặt'!F11,'SỔ CHI TIẾT BÁN HÀNG'!$N$5:$N$2863,'Đơn đặt'!E11)) -> 183000 | N11: =IF(E11="Hàng SX",0,H11-M11) -> 0 | P11: ok
A12: Bắc Sơn | B12: 46150 | C12: =D12&E12&F12 -> 30126/TB/03HH-NT00039 | D12: 301 | E12: 26/TB/03 | F12: HH-NT00039 | G12: Nhãn V5 (Red-XK) | H12: 541000 | J12: =SUMIFS('SỔ CHI TIẾT BÁN HÀNG'!$G$5:$G$2062,'SỔ CHI TIẾT BÁN HÀNG'!$C$5:$C$2062,'Đơn đặt'!F12,'SỔ CHI TIẾT BÁN HÀNG'!$L$5:$L$2062,'Đơn đặt'!C12) -> 541000 | K12: =H12+I12-J12 -> 0 | M12: =IF(E12="Hàng SX",0,SUMIFS('SỔ CHI TIẾT BÁN HÀNG'!$Q$5:$Q$2863,'SỔ CHI TIẾT BÁN HÀNG'!$C$5:$C$2863,'Đơn đặt'!F12,'SỔ CHI TIẾT BÁN HÀNG'!$N$5:$N$2863,'Đơn đặt'!E12)) -> 541000 | N12: =IF(E12="Hàng SX",0,H12-M12) -> 0 | P12: ok
A13: Bắc Sơn | B13: 46150 | C13: =D13&E13&F13 -> 301a26/YFY/03HH-CT00149 | D13: 301a | E13: 26/YFY/03 | F13: HH-CT00149 | G13: Thùng V5 (Red-XK) C5-15 | H13: 1070 | J13: =SUMIFS('SỔ CHI TIẾT BÁN HÀNG'!$G$5:$G$2062,'SỔ CHI TIẾT BÁN HÀNG'!$C$5:$C$2062,'Đơn đặt'!F13,'SỔ CHI TIẾT BÁN HÀNG'!$L$5:$L$2062,'Đơn đặt'!C13) -> 1070 | K13: =H13+I13-J13 -> 0 | M13: =IF(E13="Hàng SX",0,SUMIFS('SỔ CHI TIẾT BÁN HÀNG'!$Q$5:$Q$2863,'SỔ CHI TIẾT BÁN HÀNG'!$C$5:$C$2863,'Đơn đặt'!F13,'SỔ CHI TIẾT BÁN HÀNG'!$N$5:$N$2863,'Đơn đặt'!E13)) -> 1070 | N13: =IF(E13="Hàng SX",0,H13-M13) -> 0 | P13: ok
A14: Thanh Hoá | B14: 46031 | C14: =D14&E14&F14 -> 01/TS/26Hàng SXTP-LG00004-TH | D14: 01/TS/26 | E14: Hàng SX | F14: TP-LG00004-TH | G14: Lưỡi gà trắng 95mm x 800m x 230 (±3%) gsm (LGTTS-002) | H14: 5000 | I14: 244 | J14: =SUMIFS('SỔ CHI TIẾT BÁN HÀNG'!$G$5:$G$2062,'SỔ CHI TIẾT BÁN HÀNG'!$C$5:$C$2062,'Đơn đặt'!F14,'SỔ CHI TIẾT BÁN HÀNG'!$L$5:$L$2062,'Đơn đặt'!C14) -> 5244 | K14: =H14+I14-J14 -> 0 | L14: =+I14/H14 -> 0.0488 | M14: =IF(E14="Hàng SX",0,SUMIFS('SỔ CHI TIẾT BÁN HÀNG'!$Q$5:$Q$2863,'SỔ CHI TIẾT BÁN HÀNG'!$C$5:$C$2863,'Đơn đặt'!F14,'SỔ CHI TIẾT BÁN HÀNG'!$N$5:$N$2863,'Đơn đặt'!E14)) -> 0 | N14: =IF(E14="Hàng SX",0,H14-M14) -> 0 | P14: ok
A15: Thanh Hoá | B15: 46044 | C15: =D15&E15&F15 -> 02/TS/26Hàng SXTP-LG00004-TH | D15: 02/TS/26 | E15: Hàng SX | F15: TP-LG00004-TH | G15: Lưỡi gà trắng 95mm x 800m x 230 (±3%) gsm (LGTTS-002) | H15: 5000 | I15: 244 | J15: =SUMIFS('SỔ CHI TIẾT BÁN HÀNG'!$G$5:$G$2062,'SỔ CHI TIẾT BÁN HÀNG'!$C$5:$C$2062,'Đơn đặt'!F15,'SỔ CHI TIẾT BÁN HÀNG'!$L$5:$L$2062,'Đơn đặt'!C15) -> 5244 | K15: =H15+I15-J15 -> 0 | L15: =+I15/H15 -> 0.0488 | M15: =IF(E15="Hàng SX",0,SUMIFS('SỔ CHI TIẾT BÁN HÀNG'!$Q$5:$Q$2863,'SỔ CHI TIẾT BÁN HÀNG'!$C$5:$C$2863,'Đơn đặt'!F15,'SỔ CHI TIẾT BÁN HÀNG'!$N$5:$N$2863,'Đơn đặt'!E15)) -> 0 | N15: =IF(E15="Hàng SX",0,H15-M15) -> 0 | P15: ok
A16: Thanh Hoá | B16: 46101 | C16: =D16&E16&F16 -> 03/TS/26Hàng SXTP-LG00004-TH | D16: 03/TS/26 | E16: Hàng SX | F16: TP-LG00004-TH | G16: Lưỡi gà trắng 95mm x 800m x 230 (±3%) gsm (LGTTS-002) | H16: 5000 | I16: 244 | J16: =SUMIFS('SỔ CHI TIẾT BÁN HÀNG'!$G$5:$G$2062,'SỔ CHI TIẾT BÁN HÀNG'!$C$5:$C$2062,'Đơn đặt'!F16,'SỔ CHI TIẾT BÁN HÀNG'!$L$5:$L$2062,'Đơn đặt'!C16) -> 5244 | K16: =H16+I16-J16 -> 0 | L16: =+I16/H16 -> 0.0488 | M16: =IF(E16="Hàng SX",0,SUMIFS('SỔ CHI TIẾT BÁN HÀNG'!$Q$5:$Q$2863,'SỔ CHI TIẾT BÁN HÀNG'!$C$5:$C$2863,'Đơn đặt'!F16,'SỔ CHI TIẾT BÁN HÀNG'!$N$5:$N$2863,'Đơn đặt'!E16)) -> 0 | N16: =IF(E16="Hàng SX",0,H16-M16) -> 0 | P16: ok
A17: Thanh Hoá | B17: 46129 | C17: =D17&E17&F17 -> 04/TS/26Hàng SXTP-LG00004-TH | D17: 04/TS/26 | E17: Hàng SX | F17: TP-LG00004-TH | G17: Lưỡi gà trắng 95mm x 800m x 230 (±3%) gsm (LGTTS-002) | H17: 8000 | I17: =H17*10% -> 800 | J17: =SUMIFS('SỔ CHI TIẾT BÁN HÀNG'!$G$5:$G$2062,'SỔ CHI TIẾT BÁN HÀNG'!$C$5:$C$2062,'Đơn đặt'!F17,'SỔ CHI TIẾT BÁN HÀNG'!$L$5:$L$2062,'Đơn đặt'!C17) -> 7341.6 | K17: =H17+I17-J17 -> 1458.4 | L17: =+I17/H17 -> 0.1 | M17: =IF(E17="Hàng SX",0,SUMIFS('SỔ CHI TIẾT BÁN HÀNG'!$Q$5:$Q$2863,'SỔ CHI TIẾT BÁN HÀNG'!$C$5:$C$2863,'Đơn đặt'!F17,'SỔ CHI TIẾT BÁN HÀNG'!$N$5:$N$2863,'Đơn đặt'!E17)) -> 0 | N17: =IF(E17="Hàng SX",0,H17-M17) -> 0 | P17: ok
A18: Thăng Long | B18: 46038 | C18: =D18&E18&F18 -> 82Hàng SXTP-LG00003-TL | D18: 82 | E18: Hàng SX | F18: TP-LG00003-TL | G18: Lưỡi gà trắng 95mm x 800m x 210 (±3%) gsm (LGTPS-002) | H18: 120 | J18: =SUMIFS('SỔ CHI TIẾT BÁN HÀNG'!$G$5:$G$2062,'SỔ CHI TIẾT BÁN HÀNG'!$C$5:$C$2062,'Đơn đặt'!F18,'SỔ CHI TIẾT BÁN HÀNG'!$L$5:$L$2062,'Đơn đặt'!C18) -> 120 | K18: =H18+I18-J18 -> 0 | M18: =IF(E18="Hàng SX",0,SUMIFS('SỔ CHI TIẾT BÁN HÀNG'!$Q$5:$Q$2863,'SỔ CHI TIẾT BÁN HÀNG'!$C$5:$C$2863,'Đơn đặt'!F18,'SỔ CHI TIẾT BÁN HÀNG'!$N$5:$N$2863,'Đơn đặt'!E18)) -> 0 | N18: =IF(E18="Hàng SX",0,H18-M18) -> 0 | P18: ok
A19: Thăng Long | B19: 46038 | C19: =D19&E19&F19 -> 82Hàng SXTP-LG00002 | D19: 82 | E19: Hàng SX | F19: TP-LG00002 | G19: Lưỡi gà trắng 71mm x 800m x 210 (±3%) gsm (LGTPS-002) | H19: 1800 | J19: =SUMIFS('SỔ CHI TIẾT BÁN HÀNG'!$G$5:$G$2062,'SỔ CHI TIẾT BÁN HÀNG'!$C$5:$C$2062,'Đơn đặt'!F19,'SỔ CHI TIẾT BÁN HÀNG'!$L$5:$L$2062,'Đơn đặt'!C19) -> 1800 | K19: =H19+I19-J19 -> 0 | M19: =IF(E19="Hàng SX",0,SUMIFS('SỔ CHI TIẾT BÁN HÀNG'!$Q$5:$Q$2863,'SỔ CHI TIẾT BÁN HÀNG'!$C$5:$C$2863,'Đơn đặt'!F19,'SỔ CHI TIẾT BÁN HÀNG'!$N$5:$N$2863,'Đơn đặt'!E19)) -> 0 | N19: =IF(E19="Hàng SX",0,H19-M19) -> 0 | P19: ok
A20: Thăng Long | B20: 46055 | C20: =D20&E20&F20 -> 128Hàng SXTP-LG00003-TL | D20: 128 | E20: Hàng SX | F20: TP-LG00003-TL | G20: Lưỡi gà trắng 95mm x 800m x 210 (±3%) gsm (LGTPS-002) | H20: 60 | J20: =SUMIFS('SỔ CHI TIẾT BÁN HÀNG'!$G$5:$G$2062,'SỔ CHI TIẾT BÁN HÀNG'!$C$5:$C$2062,'Đơn đặt'!F20,'SỔ CHI TIẾT BÁN HÀNG'!$L$5:$L$2062,'Đơn đặt'!C20) -> 60 | K20: =H20+I20-J20 -> 0 | M20: =IF(E20="Hàng SX",0,SUMIFS('SỔ CHI TIẾT BÁN HÀNG'!$Q$5:$Q$2863,'SỔ CHI TIẾT BÁN HÀNG'!$C$5:$C$2863,'Đơn đặt'!F20,'SỔ CHI TIẾT BÁN HÀNG'!$N$5:$N$2863,'Đơn đặt'!E20)) -> 0 | N20: =IF(E20="Hàng SX",0,H20-M20) -> 0 | P20: ok
A21: Thăng Long | B21: 46055 | C21: =D21&E21&F21 -> 128Hàng SXTP-LG00002 | D21: 128 | E21: Hàng SX | F21: TP-LG00002 | G21: Lưỡi gà trắng 71mm x 800m x 210 (±3%) gsm (LGTPS-002) | H21: =240+600*2 -> 1440 | J21: =SUMIFS('SỔ CHI TIẾT BÁN HÀNG'!$G$5:$G$2062,'SỔ CHI TIẾT BÁN HÀNG'!$C$5:$C$2062,'Đơn đặt'!F21,'SỔ CHI TIẾT BÁN HÀNG'!$L$5:$L$2062,'Đơn đặt'!C21) -> 1440 | K21: =H21+I21-J21 -> 0 | M21: =IF(E21="Hàng SX",0,SUMIFS('SỔ CHI TIẾT BÁN HÀNG'!$Q$5:$Q$2863,'SỔ CHI TIẾT BÁN HÀNG'!$C$5:$C$2863,'Đơn đặt'!F21,'SỔ CHI TIẾT BÁN HÀNG'!$N$5:$N$2863,'Đơn đặt'!E21)) -> 0 | N21: =IF(E21="Hàng SX",0,H21-M21) -> 0 | P21: ok
A22: Thăng Long | B22: 46055 | C22: =D22&E22&F22 -> 128Hàng SXTP-LG00004-TL | D22: 128 | E22: Hàng SX | F22: TP-LG00004-TL | G22: Lưỡi gà trắng 91mm x 800m x 210 (±3%) gsm (LGTPS-002) | H22: 30 | J22: =SUMIFS('SỔ CHI TIẾT BÁN HÀNG'!$G$5:$G$2062,'SỔ CHI TIẾT BÁN HÀNG'!$C$5:$C$2062,'Đơn đặt'!F22,'SỔ CHI TIẾT BÁN HÀNG'!$L$5:$L$2062,'Đơn đặt'!C22) -> 30 | K22: =H22+I22-J22 -> 0 | M22: =IF(E22="Hàng SX",0,SUMIFS('SỔ CHI TIẾT BÁN HÀNG'!$Q$5:$Q$2863,'SỔ CHI TIẾT BÁN HÀNG'!$C$5:$C$2863,'Đơn đặt'!F22,'SỔ CHI TIẾT BÁN HÀNG'!$N$5:$N$2863,'Đơn đặt'!E22)) -> 0 | N22: =IF(E22="Hàng SX",0,H22-M22) -> 0 | P22: ok
A23: Thăng Long | B23: 46079 | C23: =D23&E23&F23 -> 184Hàng SXTP-LG00003-TL | D23: 184 | E23: Hàng SX | F23: TP-LG00003-TL | G23: Lưỡi gà trắng 95mm x 800m x 210 (±3%) gsm (LGTPS-002) | H23: 120 | J23: =SUMIFS('SỔ CHI TIẾT BÁN HÀNG'!$G$5:$G$2062,'SỔ CHI TIẾT BÁN HÀNG'!$C$5:$C$2062,'Đơn đặt'!F23,'SỔ CHI TIẾT BÁN HÀNG'!$L$5:$L$2062,'Đơn đặt'!C23) -> 120 | K23: =H23+I23-J23 -> 0 | M23: =IF(E23="Hàng SX",0,SUMIFS('SỔ CHI TIẾT BÁN HÀNG'!$Q$5:$Q$2863,'SỔ CHI TIẾT BÁN HÀNG'!$C$5:$C$2863,'Đơn đặt'!F23,'SỔ CHI TIẾT BÁN HÀNG'!$N$5:$N$2863,'Đơn đặt'!E23)) -> 0 | N23: =IF(E23="Hàng SX",0,H23-M23) -> 0 | P23: ok
A24: Thăng Long | B24: 46093 | C24: =D24&E24&F24 -> 239Hàng SXTP-LG00003-TL | D24: 239 | E24: Hàng SX | F24: TP-LG00003-TL | G24: Lưỡi gà trắng 95mm x 800m x 210 (±3%) gsm (LGTPS-002) | H24: 180 | J24: =SUMIFS('SỔ CHI TIẾT BÁN HÀNG'!$G$5:$G$2062,'SỔ CHI TIẾT BÁN HÀNG'!$C$5:$C$2062,'Đơn đặt'!F24,'SỔ CHI TIẾT BÁN HÀNG'!$L$5:$L$2062,'Đơn đặt'!C24) -> 180 | K24: =H24+I24-J24 -> 0 | M24: =IF(E24="Hàng SX",0,SUMIFS('SỔ CHI TIẾT BÁN HÀNG'!$Q$5:$Q$2863,'SỔ CHI TIẾT BÁN HÀNG'!$C$5:$C$2863,'Đơn đặt'!F24,'SỔ CHI TIẾT BÁN HÀNG'!$N$5:$N$2863,'Đơn đặt'!E24)) -> 0 | N24: =IF(E24="Hàng SX",0,H24-M24) -> 0 | P24: ok
A25: Thăng Long | B25: 46093 | C25: =D25&E25&F25 -> 239Hàng SXTP-LG00005 | D25: 239 | E25: Hàng SX | F25: TP-LG00005 | G25: Lưỡi gà trắng 83mm x 800m x 210 (±3%) gsm (LGTPS-002) | H25: 60 | J25: =SUMIFS('SỔ CHI TIẾT BÁN HÀNG'!$G$5:$G$2062,'SỔ CHI TIẾT BÁN HÀNG'!$C$5:$C$2062,'Đơn đặt'!F25,'SỔ CHI TIẾT BÁN HÀNG'!$L$5:$L$2062,'Đơn đặt'!C25) -> 60 | K25: =H25+I25-J25 -> 0 | M25: =IF(E25="Hàng SX",0,SUMIFS('SỔ CHI TIẾT BÁN HÀNG'!$Q$5:$Q$2863,'SỔ CHI TIẾT BÁN HÀNG'!$C$5:$C$2863,'Đơn đặt'!F25,'SỔ CHI TIẾT BÁN HÀNG'!$N$5:$N$2863,'Đơn đặt'!E25)) -> 0 | N25: =IF(E25="Hàng SX",0,H25-M25) -> 0 | P25: ok
A26: Thăng Long | B26: 46093 | C26: =D26&E26&F26 -> 239Hàng SXTP-LG00002 | D26: 239 | E26: Hàng SX | F26: TP-LG00002 | G26: Lưỡi gà trắng 71mm x 800m x 210 (±3%) gsm (LGTPS-002) | H26: 600 | J26: =SUMIFS('SỔ CHI TIẾT BÁN HÀNG'!$G$5:$G$2062,'SỔ CHI TIẾT BÁN HÀNG'!$C$5:$C$2062,'Đơn đặt'!F26,'SỔ CHI TIẾT BÁN HÀNG'!$L$5:$L$2062,'Đơn đặt'!C26) -> 600 | K26: =H26+I26-J26 -> 0 | M26: =IF(E26="Hàng SX",0,SUMIFS('SỔ CHI TIẾT BÁN HÀNG'!$Q$5:$Q$2863,'SỔ CHI TIẾT BÁN HÀNG'!$C$5:$C$2863,'Đơn đặt'!F26,'SỔ CHI TIẾT BÁN HÀNG'!$N$5:$N$2863,'Đơn đặt'!E26)) -> 0 | N26: =IF(E26="Hàng SX",0,H26-M26) -> 0 | P26: ok
A27: Thăng Long | B27: 46108 | C27: =D27&E27&F27 -> 294Hàng SXTP-LG00005-TL | D27: 294 | E27: Hàng SX | F27: TP-LG00005-TL | G27: Lưỡi gà trắng 96.5mm x 800m x 210 (±3%) gsm (LGTPS-002) | H27: 22 | J27: =SUMIFS('SỔ CHI TIẾT BÁN HÀNG'!$G$5:$G$2062,'SỔ CHI TIẾT BÁN HÀNG'!$C$5:$C$2062,'Đơn đặt'!F27,'SỔ CHI TIẾT BÁN HÀNG'!$L$5:$L$2062,'Đơn đặt'!C27) -> 22 | K27: =H27+I27-J27 -> 0 | M27: =IF(E27="Hàng SX",0,SUMIFS('SỔ CHI TIẾT BÁN HÀNG'!$Q$5:$Q$2863,'SỔ CHI TIẾT BÁN HÀNG'!$C$5:$C$2863,'Đơn đặt'!F27,'SỔ CHI TIẾT BÁN HÀNG'!$N$5:$N$2863,'Đơn đặt'!E27)) -> 0 | N27: =IF(E27="Hàng SX",0,H27-M27) -> 0 | P27: ok
A28: Thăng Long | B28: 46113 | C28: =D28&E28&F28 -> 30926/THP/01HH-CT00037 | D28: 309 | E28: 26/THP/01 | F28: HH-CT00037 | G28: Thùng carton C48 5 lớp 15kg | H28: 1000 | J28: =SUMIFS('SỔ CHI TIẾT BÁN HÀNG'!$G$5:$G$2062,'SỔ CHI TIẾT BÁN HÀNG'!$C$5:$C$2062,'Đơn đặt'!F28,'SỔ CHI TIẾT BÁN HÀNG'!$L$5:$L$2062,'Đơn đặt'!C28) -> 1000 | K28: =H28+I28-J28 -> 0 | M28: =IF(E28="Hàng SX",0,SUMIFS('SỔ CHI TIẾT BÁN HÀNG'!$Q$5:$Q$2863,'SỔ CHI TIẾT BÁN HÀNG'!$C$5:$C$2863,'Đơn đặt'!F28,'SỔ CHI TIẾT BÁN HÀNG'!$N$5:$N$2863,'Đơn đặt'!E28)) -> 1000 | N28: =IF(E28="Hàng SX",0,H28-M28) -> 0 | P28: ok
A29: Thăng Long | B29: 46148 | C29: =D29&E29&F29 -> 44426/THP/02HH-CT00037 | D29: 444 | E29: 26/THP/02 | F29: HH-CT00037 | G29: Thùng carton C48 5 lớp 15kg | H29: 2000 | J29: =SUMIFS('SỔ CHI TIẾT BÁN HÀNG'!$G$5:$G$2062,'SỔ CHI TIẾT BÁN HÀNG'!$C$5:$C$2062,'Đơn đặt'!F29,'SỔ CHI TIẾT BÁN HÀNG'!$L$5:$L$2062,'Đơn đặt'!C29) -> 1606 | K29: =H29+I29-J29 -> 394 | M29: =IF(E29="Hàng SX",0,SUMIFS('SỔ CHI TIẾT BÁN HÀNG'!$Q$5:$Q$2863,'SỔ CHI TIẾT BÁN HÀNG'!$C$5:$C$2863,'Đơn đặt'!F29,'SỔ CHI TIẾT BÁN HÀNG'!$N$5:$N$2863,'Đơn đặt'!E29)) -> 1606 | N29: =IF(E29="Hàng SX",0,H29-M29) -> 394 | P29: ok
A30: Sài gòn | B30: 45965 | C30: =D30&E30&F30 -> 11/08/TSC-LTHàng SXTP-LG00008-SG | D30: 11/08/TSC-LT | E30: Hàng SX | F30: TP-LG00008-SG | G30: Giấy lưỡi gà trắng - LGT90-TS 90mm x 800m x 250gsm | H30: 2808 | J30: =SUMIFS('SỔ CHI TIẾT BÁN HÀNG'!$G$5:$G$2062,'SỔ CHI TIẾT BÁN HÀNG'!$C$5:$C$2062,'Đơn đặt'!F30,'SỔ CHI TIẾT BÁN HÀNG'!$L$5:$L$2062,'Đơn đặt'!C30) -> 2808 | K30: =H30+I30-J30 -> 0 | M30: =IF(E30="Hàng SX",0,SUMIFS('SỔ CHI TIẾT BÁN HÀNG'!$Q$5:$Q$2863,'SỔ CHI TIẾT BÁN HÀNG'!$C$5:$C$2863,'Đơn đặt'!F30,'SỔ CHI TIẾT BÁN HÀNG'!$N$5:$N$2863,'Đơn đặt'!E30)) -> 0 | N30: =IF(E30="Hàng SX",0,H30-M30) -> 0 | P30: ok
A31: Sài gòn | B31: 45982 | C31: =D31&E31&F31 -> 11-10-TS136-2025/TS-AVP/ĐĐHHH-CT00072 | D31: 11-10-TS | E31: 136-2025/TS-AVP/ĐĐH | F31: HH-CT00072 | G31: Thùng carton SÀI GÒN Vàng BC-TĐ | H31: 500 | J31: =SUMIFS('SỔ CHI TIẾT BÁN HÀNG'!$G$5:$G$2062,'SỔ CHI TIẾT BÁN HÀNG'!$C$5:$C$2062,'Đơn đặt'!F31,'SỔ CHI TIẾT BÁN HÀNG'!$L$5:$L$2062,'Đơn đặt'!C31) -> 500 | K31: =H31+I31-J31 -> 0 | M31: =IF(E31="Hàng SX",0,SUMIFS('SỔ CHI TIẾT BÁN HÀNG'!$Q$5:$Q$2863,'SỔ CHI TIẾT BÁN HÀNG'!$C$5:$C$2863,'Đơn đặt'!F31,'SỔ CHI TIẾT BÁN HÀNG'!$N$5:$N$2863,'Đơn đặt'!E31)) -> 500 | N31: =IF(E31="Hàng SX",0,H31-M31) -> 0 | P31: ok
A32: Sài gòn | B32: 45982 | C32: =D32&E32&F32 -> 11-10-TS137-2025/TS-AVP/ĐĐHHH-CT00007 | D32: 11-10-TS | E32: 137-2025/TS-AVP/ĐĐH | F32: HH-CT00007 | G32: Thùng carton SAIGON Silver DS-TĐ | H32: 46800 | J32: =SUMIFS('SỔ CHI TIẾT BÁN HÀNG'!$G$5:$G$2062,'SỔ CHI TIẾT BÁN HÀNG'!$C$5:$C$2062,'Đơn đặt'!F32,'SỔ CHI TIẾT BÁN HÀNG'!$L$5:$L$2062,'Đơn đặt'!C32) -> 46800 | K32: =H32+I32-J32 -> 0 | M32: =IF(E32="Hàng SX",0,SUMIFS('SỔ CHI TIẾT BÁN HÀNG'!$Q$5:$Q$2863,'SỔ CHI TIẾT BÁN HÀNG'!$C$5:$C$2863,'Đơn đặt'!F32,'SỔ CHI TIẾT BÁN HÀNG'!$N$5:$N$2863,'Đơn đặt'!E32)) -> 46800 | N32: =IF(E32="Hàng SX",0,H32-M32) -> 0 | P32: ok
A33: Sài gòn | B33: 45982 | C33: =D33&E33&F33 -> 11-10-TS137-2025/TS-AVP/ĐĐHHH-CT00008 | D33: 11-10-TS | E33: 137-2025/TS-AVP/ĐĐH | F33: HH-CT00008 | G33: Thùng carton SAIGON Silver DS-B-TĐ | H33: 9000 | J33: =SUMIFS('SỔ CHI TIẾT BÁN HÀNG'!$G$5:$G$2062,'SỔ CHI TIẾT BÁN HÀNG'!$C$5:$C$2062,'Đơn đặt'!F33,'SỔ CHI TIẾT BÁN HÀNG'!$L$5:$L$2062,'Đơn đặt'!C33) -> 9000 | K33: =H33+I33-J33 -> 0 | M33: =IF(E33="Hàng SX",0,SUMIFS('SỔ CHI TIẾT BÁN HÀNG'!$Q$5:$Q$2863,'SỔ CHI TIẾT BÁN HÀNG'!$C$5:$C$2863,'Đơn đặt'!F33,'SỔ CHI TIẾT BÁN HÀNG'!$N$5:$N$2863,'Đơn đặt'!E33)) -> 9000 | N33: =IF(E33="Hàng SX",0,H33-M33) -> 0 | P33: ok
A34: Sài gòn | B34: 46001 | C34: =D34&E34&F34 -> 12-01-TS146-2025/TS-AVP/ĐĐHHH-CT00072 | D34: 12-01-TS | E34: 146-2025/TS-AVP/ĐĐH | F34: HH-CT00072 | G34: Thùng carton SÀI GÒN Vàng BC-TĐ | H34: 12000 | J34: =SUMIFS('SỔ CHI TIẾT BÁN HÀNG'!$G$5:$G$2062,'SỔ CHI TIẾT BÁN HÀNG'!$C$5:$C$2062,'Đơn đặt'!F34,'SỔ CHI TIẾT BÁN HÀNG'!$L$5:$L$2062,'Đơn đặt'!C34) -> 12000 | K34: =H34+I34-J34 -> 0 | M34: =IF(E34="Hàng SX",0,SUMIFS('SỔ CHI TIẾT BÁN HÀNG'!$Q$5:$Q$2863,'SỔ CHI TIẾT BÁN HÀNG'!$C$5:$C$2863,'Đơn đặt'!F34,'SỔ CHI TIẾT BÁN HÀNG'!$N$5:$N$2863,'Đơn đặt'!E34)) -> 12000 | N34: =IF(E34="Hàng SX",0,H34-M34) -> 0 | P34: ok
A35: Sài gòn | B35: 46014 | C35: =D35&E35&F35 -> 12-09-TS149-2025/TS-AVP/ĐĐHHH-CT00064 | D35: 12-09-TS | E35: 149-2025/TS-AVP/ĐĐH | F35: HH-CT00064 | G35: Thùng carton GREENHILL 100SP MENTHOL | H35: 8000 | J35: =SUMIFS('SỔ CHI TIẾT BÁN HÀNG'!$G$5:$G$2062,'SỔ CHI TIẾT BÁN HÀNG'!$C$5:$C$2062,'Đơn đặt'!F35,'SỔ CHI TIẾT BÁN HÀNG'!$L$5:$L$2062,'Đơn đặt'!C35) -> 8000 | K35: =H35+I35-J35 -> 0 | M35: =IF(E35="Hàng SX",0,SUMIFS('SỔ CHI TIẾT BÁN HÀNG'!$Q$5:$Q$2863,'SỔ CHI TIẾT BÁN HÀNG'!$C$5:$C$2863,'Đơn đặt'!F35,'SỔ CHI TIẾT BÁN HÀNG'!$N$5:$N$2863,'Đơn đặt'!E35)) -> 8000 | N35: =IF(E35="Hàng SX",0,H35-M35) -> 0 | P35: ok
A36: Sài gòn | B36: 46016 | C36: =D36&E36&F36 -> 12-38/TS-LP150-2025/TS-AVP/ĐĐHTP-PE00004 | D36: 12-38/TS-LP | E36: 150-2025/TS-AVP/ĐĐH | F36: TP-PE00004 | G36: Túi PE 52*100cm | H36: 4000 | J36: =SUMIFS('SỔ CHI TIẾT BÁN HÀNG'!$G$5:$G$2062,'SỔ CHI TIẾT BÁN HÀNG'!$C$5:$C$2062,'Đơn đặt'!F36,'SỔ CHI TIẾT BÁN HÀNG'!$L$5:$L$2062,'Đơn đặt'!C36) -> 4000 | K36: =H36+I36-J36 -> 0 | M36: =IF(E36="Hàng SX",0,SUMIFS('SỔ CHI TIẾT BÁN HÀNG'!$Q$5:$Q$2863,'SỔ CHI TIẾT BÁN HÀNG'!$C$5:$C$2863,'Đơn đặt'!F36,'SỔ CHI TIẾT BÁN HÀNG'!$N$5:$N$2863,'Đơn đặt'!E36)) -> 4000 | N36: =IF(E36="Hàng SX",0,H36-M36) -> 0 | P36: ok
A37: Sài gòn | B37: 46016 | C37: =D37&E37&F37 -> 12-38/TS-LP150-2025/TS-AVP/ĐĐHTP-PE00006 | D37: 12-38/TS-LP | E37: 150-2025/TS-AVP/ĐĐH | F37: TP-PE00006 | G37: Túi PE 85 x 70cm | H37: 1000 | J37: =SUMIFS('SỔ CHI TIẾT BÁN HÀNG'!$G$5:$G$2062,'SỔ CHI TIẾT BÁN HÀNG'!$C$5:$C$2062,'Đơn đặt'!F37,'SỔ CHI TIẾT BÁN HÀNG'!$L$5:$L$2062,'Đơn đặt'!C37) -> 1000 | K37: =H37+I37-J37 -> 0 | M37: =IF(E37="Hàng SX",0,SUMIFS('SỔ CHI TIẾT BÁN HÀNG'!$Q$5:$Q$2863,'SỔ CHI TIẾT BÁN HÀNG'!$C$5:$C$2863,'Đơn đặt'!F37,'SỔ CHI TIẾT BÁN HÀNG'!$N$5:$N$2863,'Đơn đặt'!E37)) -> 1000 | N37: =IF(E37="Hàng SX",0,H37-M37) -> 0 | P37: ok
A38: Sài gòn | B38: 46016 | C38: =D38&E38&F38 -> 12-38/TS-LP150-2025/TS-AVP/ĐĐHTP-PE00001 | D38: 12-38/TS-LP | E38: 150-2025/TS-AVP/ĐĐH | F38: TP-PE00001 | G38: Túi PE 54*92cm | H38: 14000 | J38: =SUMIFS('SỔ CHI TIẾT BÁN HÀNG'!$G$5:$G$2062,'SỔ CHI TIẾT BÁN HÀNG'!$C$5:$C$2062,'Đơn đặt'!F38,'SỔ CHI TIẾT BÁN HÀNG'!$L$5:$L$2062,'Đơn đặt'!C38) -> 14000 | K38: =H38+I38-J38 -> 0 | M38: =IF(E38="Hàng SX",0,SUMIFS('SỔ CHI TIẾT BÁN HÀNG'!$Q$5:$Q$2863,'SỔ CHI TIẾT BÁN HÀNG'!$C$5:$C$2863,'Đơn đặt'!F38,'SỔ CHI TIẾT BÁN HÀNG'!$N$5:$N$2863,'Đơn đặt'!E38)) -> 14000 | N38: =IF(E38="Hàng SX",0,H38-M38) -> 0 | P38: ok
A39: Sài gòn | B39: 45965 | C39: =D39&E39&F39 -> 11-04-TS01-2026/TS-AVP/ĐĐHHH-CT00025 | D39: 11-04-TS | E39: 01-2026/TS-AVP/ĐĐH | F39: HH-CT00025 | G39: Thùng carton ERA Premium - OD | H39: 11490 | J39: =SUMIFS('SỔ CHI TIẾT BÁN HÀNG'!$G$5:$G$2062,'SỔ CHI TIẾT BÁN HÀNG'!$C$5:$C$2062,'Đơn đặt'!F39,'SỔ CHI TIẾT BÁN HÀNG'!$L$5:$L$2062,'Đơn đặt'!C39) -> 11490 | K39: =H39+I39-J39 -> 0 | M39: =IF(E39="Hàng SX",0,SUMIFS('SỔ CHI TIẾT BÁN HÀNG'!$Q$5:$Q$2863,'SỔ CHI TIẾT BÁN HÀNG'!$C$5:$C$2863,'Đơn đặt'!F39,'SỔ CHI TIẾT BÁN HÀNG'!$N$5:$N$2863,'Đơn đặt'!E39)) -> 11490 | N39: =IF(E39="Hàng SX",0,H39-M39) -> 0 | P39: ok
A40: Sài gòn | B40: 45965 | C40: =D40&E40&F40 -> 11-04-TS01-2026/TS-AVP/ĐĐHHH-CT00031 | D40: 11-04-TS | E40: 01-2026/TS-AVP/ĐĐH | F40: HH-CT00031 | G40: Thùng carton ERA BLACK MENTHOL | H40: 11430 | J40: =SUMIFS('SỔ CHI TIẾT BÁN HÀNG'!$G$5:$G$2062,'SỔ CHI TIẾT BÁN HÀNG'!$C$5:$C$2062,'Đơn đặt'!F40,'SỔ CHI TIẾT BÁN HÀNG'!$L$5:$L$2062,'Đơn đặt'!C40) -> 11430 | K40: =H40+I40-J40 -> 0 | M40: =IF(E40="Hàng SX",0,SUMIFS('SỔ CHI TIẾT BÁN HÀNG'!$Q$5:$Q$2863,'SỔ CHI TIẾT BÁN HÀNG'!$C$5:$C$2863,'Đơn đặt'!F40,'SỔ CHI TIẾT BÁN HÀNG'!$N$5:$N$2863,'Đơn đặt'!E40)) -> 11430 | N40: =IF(E40="Hàng SX",0,H40-M40) -> 0 | P40: ok
...

Sheet Sheet1
E15: Túi PE 85x70cm | F15: TP-PE00006
E16: TÚI PE 54*92CM | F16: TP-PE00001
E17: TÚI PE 52*100CM | F17: TP-PE00001
E18: NHÃN DU LỊCH đỏ BM | F18: HH-NT00013
E19: NHÃN HÒA BÌNH BM | F19: HH-NT00011
E20: Tút ĐÀ LẠT KĐL | F20: HH-CT00112
E21: Thùng carton COTAB BC-TĐ | F21: HH-CT00036
E22: Thùng carton ĐÀ LẠT Xanh BC-TĐ | F22: HH-CT00081
E23: Thùng carton DU LỊCH Đỏ BM-TĐ | F23: HH-CT00028
E24: Thùng carton FASOL BM-TĐ | F24: HH-CT00038
E25: Thùng carton FASOL Vàng BC-TĐ | F25: HH-CT00089
E26: Thùng carton HÒA BÌNH BM-TĐ | F26: HH-CT00006
... E28: Thùng carton MELIA Ment BC-TĐ | F28: HH-CT00078
E29: Thùng carton SÀI GÒN Xanh BC- TĐ | F29: #N/A
E30: Thùng carton SAIGON Silver DS-TĐ | F30: HH-CT00007
E31: Thùng carton SAIGON Silver DS-B-TĐ | F31: HH-CT00008
E32: Thùng carton SÀI GÒN Vàng BC-TĐ | F32: HH-CT00072
E33: Thùng carton SAIGON SILVER CAPSULE DS BC | F33: HH-CT00131
